Workbook

Sheet Instructions
A1: OpenAlex R2+A1 Baseline — Blind Human Audit
A3: 目的：各 OpenAlex record が、指定された target literary work を実際に参照しているかを、LLM判定を見ずに監査します。
A5: 判定 | B5: 意味 | D5: Review rules
A6: VALID_TARGET_REFERENCE | B6: 表示された情報から、対象作品への参照が十分に確認できる。 | D6: 1 | E6: Web検索はしない。
A7: INVALID_TARGET_REFERENCE | B7: 表示された情報から、対象作品への参照ではないと確認できる。 | D7: 2 | E7: LLMのcandidate-level判定・sampling stratum・risk featureは見ない。
A8: UNCERTAIN | B8: 表示された情報だけでは valid / invalid を確実に決められない。 | D8: 3 | E8: substantive analysis の有無ではなく、target workへの参照そのものを判定する。
D9: 4 | E9: primary text / bibliography / review / brief mention でも、target workを実際に指せばVALIDになり得る。
D10: 5 | E10: INVALID / UNCERTAIN は Reviewer note に短い根拠を書く。
A12: Batch | B12: Completed | C12: VALID | D12: INVALID | E12: UNCERTAIN | F12: Total
A13: Audit 01 | B13: =SUM(C13:E13) -> 25 | C13: =COUNTIF('Audit 01'!I6:I30,"VALID_TARGET_REFERENCE") -> 23 | D13: =COUNTIF('Audit 01'!I6:I30,"INVALID_TARGET_REFERENCE") -> 2 | E13: =COUNTIF('Audit 01'!I6:I30,"UNCERTAIN") -> 0 | F13: 25
A14: Audit 02 | B14: =SUM(C14:E14) -> 25 | C14: =COUNTIF('Audit 02'!I6:I30,"VALID_TARGET_REFERENCE") -> 23 | D14: =COUNTIF('Audit 02'!I6:I30,"INVALID_TARGET_REFERENCE") -> 2 | E14: =COUNTIF('Audit 02'!I6:I30,"UNCERTAIN") -> 0 | F14: 25
A15: Audit 03 | B15: =SUM(C15:E15) -> 25 | C15: =COUNTIF('Audit 03'!I6:I30,"VALID_TARGET_REFERENCE") -> 21 | D15: =COUNTIF('Audit 03'!I6:I30,"INVALID_TARGET_REFERENCE") -> 4 | E15: =COUNTIF('Audit 03'!I6:I30,"UNCERTAIN") -> 0 | F15: 25
A16: Audit 04 | B16: =SUM(C16:E16) -> 25 | C16: =COUNTIF('Audit 04'!I6:I30,"VALID_TARGET_REFERENCE") -> 23 | D16: =COUNTIF('Audit 04'!I6:I30,"INVALID_TARGET_REFERENCE") -> 0 | E16: =COUNTIF('Audit 04'!I6:I30,"UNCERTAIN") -> 2 | F16: 25
A17: Audit 05 | B17: =SUM(C17:E17) -> 25 | C17: =COUNTIF('Audit 05'!I6:I30,"VALID_TARGET_REFERENCE") -> 21 | D17: =COUNTIF('Audit 05'!I6:I30,"INVALID_TARGET_REFERENCE") -> 2 | E17: =COUNTIF('Audit 05'!I6:I30,"UNCERTAIN") -> 2 | F17: 25
A18: Audit 06 | B18: =SUM(C18:E18) -> 25 | C18: =COUNTIF('Audit 06'!I6:I30,"VALID_TARGET_REFERENCE") -> 22 | D18: =COUNTIF('Audit 06'!I6:I30,"INVALID_TARGET_REFERENCE") -> 3 | E18: =COUNTIF('Audit 06'!I6:I30,"UNCERTAIN") -> 0 | F18: 25
A19: TOTAL | B19: =SUM(B13:B18) -> 150 | C19: =SUM(C13:C18) -> 133 | D19: =SUM(D13:D18) -> 13 | E19: =SUM(E13:E18) -> 4 | F19: 150
A22: Judgment | B22: Reason code | C22: Meaning
A23: VALID | B23: DIRECT_TARGET_REFERENCE | C23: Explicit title/work + author linkage identifies the target.
A24: VALID | B24: VALID_TITLE_VARIANT | C24: Supported alternate/shortened/translated title denotes the same target.
A25: VALID | B25: VALID_CONTEXTUAL_REFERENCE | C25: Context sufficiently identifies the target without direct bibliographic naming.
A26: INVALID | B26: TITLE_COLLISION_DIFFERENT_WORK | C26: Matching title denotes a different work.
A27: INVALID | B27: GENERIC_OR_LEXICAL_TITLE_USE | C27: Matched expression is ordinary/generic language, not the target title.
A28: INVALID | B28: AUTHOR_COLLISION_DIFFERENT_PERSON | C28: Matched author name denotes another person.
A29: INVALID | B29: TITLE_AUTHOR_UNLINKED_COOCCURRENCE | C29: Title expression and author appear but are not semantically linked as the target.
A30: INVALID | B30: WRONG_WORK_SAME_AUTHOR | C30: A different work by the same author is identified.
A31: INVALID | B31: ALIAS_NOT_TARGET_EQUIVALENT | C31: The apparent target/title relationship is not the same underlying work.
A32: INVALID | B32: METADATA_TEXT_ARTIFACT | C32: A metadata/text artifact causes the false match.
A33: INVALID | B33: OTHER | C33: Established invalidity outside the listed reasons; explain in note.
... A35: UNCERTAIN | B35: AMBIGUOUS_TARGET_REFERENCE | C35: Specific competing work identities remain unresolved.
A38: Provenance / safeguards
A39: Frozen human-audit sample | B39: 150 candidates / 90 project works / 6 batches × 25
A40: Repository branch | B40: kakenc-integration-20260927
A41: Frozen packet commit | B41: 6260c82f9883762b46a3b4384e70d037278ac886
A42: Blinding | B42: LLM candidate judgments, LLM strata, analysis weights, and retrieval-risk features are absent from this workbook.

Sheet Lists
A1: Judgment | B1: Confidence | C1: Reason code | E1: Do not edit — validation source lists.
A2: VALID_TARGET_REFERENCE | B2: HIGH | C2: DIRECT_TARGET_REFERENCE
A3: INVALID_TARGET_REFERENCE | B3: MEDIUM | C3: VALID_TITLE_VARIANT
A4: UNCERTAIN | B4: LOW | C4: VALID_CONTEXTUAL_REFERENCE
C5: TITLE_COLLISION_DIFFERENT_WORK
C6: GENERIC_OR_LEXICAL_TITLE_USE
C7: AUTHOR_COLLISION_DIFFERENT_PERSON
C8: TITLE_AUTHOR_UNLINKED_COOCCURRENCE
C9: WRONG_WORK_SAME_AUTHOR
C10: ALIAS_NOT_TARGET_EQUIVALENT
C11: METADATA_TEXT_ARTIFACT
C12: OTHER
C13: INSUFFICIENT_CONTEXT
C14: AMBIGUOUS_TARGET_REFERENCE

Sheet Audit 01
A1: OpenAlex R2+A1 Blind Human Audit — R2A1A01
A2: 判定対象：OpenAlex record が target literary work を本当に参照しているか。LLM判定・sampling stratum・risk featureは非表示です。Web検索はしません。
A4: 入力欄 → | I4: Judgment | J4: Confidence | K4: Reason | L4: Reviewer note
A5: Review # | B5: Target title | C5: Target author | D5: OpenAlex record title | E5: OpenAlex abstract | F5: Year | G5: Publication date | H5: DOI | I5: Judgment | J5: Confidence | K5: Reason | L5: Reviewer note | M5: Candidate ID | N5: Project Work ID | O5: OpenAlex Work ID
A6: 1 | B6: Henry James | C6: Henry James | D6: Naming the father: legacies, genealogies, and explorations of fatherhood in modern and contemporary literature | E6: chapter 1 Acknowledgments chapter 2 Introduction: Naming the Dead chapter 3 Part One: in Memory. Business of Mourning chapter 4 Two Fingers of Chat chapter 5 Culture of My Childhood. Part Two: Fathers in Ethnic Culture. Performative Fathers and the Inessential Macho: Fatherhood in Contemporary Latino/Latina Literature chapter 6 Negations and Subversions of Paternal Authorities in Glissant's Fictional Works (Le Quatrime Sicle, La Case du commandeur, Tout-monde) chapter 7 Holy and Unholy Ghosts: Legacy of the in the Plays of August Wilson. Part Three: Fathers and Daughters. Legacy of The Unspeakable Father in Henry James's Wings of the Dove chapter 8 Generating Alternative Representations of Fatherhood: Anzia Yezierska and Dorothy Canfield Fisher's Narrative Spaces for Male Others chapter 9 Daughters of Memory: Modernist Poet as Father. Part Four: Beyond the Father. Oedipus and the Modernist Aesthetic: Reconceiving the Social in Rebecca West's Return of the Soldier chapter 10 Naming the Father: Genealogy, Spectacle, and Jack Nicholson in Going Native chapter 11 Original Chaos Restored: Paternal Fictions in William S. Burroughs chapter 12 Works Cited chapter 13 Index | F6: 2001.0 | G6: 2001-01-01 | H6: https://doi.org/10.5860/choice.38-2616 | I6: VALID_TARGET_REFERENCE | J6: HIGH | K6: DIRECT_TARGET_REFERENCE | L6: 著者名ターゲット：Wings of the Dove を扱う章あり | M6: OABASEV1_fff0b83e8226a6c7 | N6: W000014024 | O6: W2953498596
A7: 2 | B7: The years | C7: Virginia Woolf | D7: Beyond the Five Towns: a re-evaluation of Arnold Bennett | E7: ‘I have a great deal to say, and I mean to say it. As for my work being taken seriously, we shall see about that’. Arnold Bennett, 1909 (Bennett, letter to Pinker dated 17 May 1909, in Letters, Vol. I, p. 123.) Arnold Bennett occupies a somewhat anomalous position as an Edwardian realist in a century dominated by modernist aesthetics. Pigeonholed by critics who have tended to adopt an overly formalist approach when considering his fiction, Bennett’s critical acclaim has predominantly been restricted to his Five Towns novels and has been advocated through readings which arrogate to him a slavish homage to nineteenth-century French naturalism and a quasi-documentary representation of particular locales. This dissertation aims to challenge Bennett’s categorisation as a merely provincial author, and as an Edwardian deserving of the canonical segregation initially proposed by Virginia Woolf, which separates his work from – and subordinates it to – that of his early twentieth-century or early Modernist contemporaries. To this end, I will demonstrate that Bennett was in fact, readily incorporating early twentieth-century themes and techniques, and actively engaging with various aspects of individual, social and national politics in comparable ways to other Modernists. I will also contend – contrary to critics who have regarded the war as having killed Bennett’s creativity – that the war occasioned a shift in Bennett’s agenda that, though not appreciated in his time or in the years after his death, is now in need of re-evaluation. With respect to methodology, this dissertation contextualises Bennett’s artistic strategies in light of early twentieth-century aesthetic concerns, and it demonstrates that his prose techniques serve social and/or political purposes. The thesis is divided into three chapters, each of which explores a stage of Bennett’s literary career. Chapter I covers 1898, the year of publication for Bennett’s first novel, The Man from the North, to 1913, also analysing A Great Man (1904) and Buried Alive (1908). Chapter II attends to Bennett’s fictional and non-fictional writings of the War years, including The Roll-Call (1919) – which begins in 1901 and culminates in 1914 – Liberty (1914), and Over There (1915). Chapter III examines Bennett’s writing from 1919 onwards, focusing on three novels: Riceyman Steps (1923), Lord Raingo (1926), and Accident (1929). | F7: 2020.0 | G7: 2020-03-01 | I7: INVALID_TARGET_REFERENCE | J7: HIGH | K7: GENERIC_OR_LEXICAL_TITLE_USE | L7: Woolfは言及されるが「The Years」は未言及。"the years after his death"は一般語 | M7: OABASEV1_5b3983b28a67c900 | N7: W000018226 | O7: W6989607625
A8: 3 | B8: Santa | C8: Federico Gamboa | D8: Subversión del mito de Ciudad de México como Nueva Jerusalén en Santa de Gamboa | E8: Santa (1903) de Federico Gamboa se publica durante el regimen dictatorial de Porfirio Diaz para cuestionar, por un lado, sus dos maximas de “orden y progreso”, al tiempo que para analizar a sociedad de su tiempo y evolucion historica e ideologa de Iglesia colonial en Nueva Espana. Esta Iglesia transculturizo el mito utopico de Jerusalen en Ciudad de Mexico para propagar la grandeza mexicana y, por extension, del Imperio colonial espanol. Santa-prostituta, protagonista de novela y alegoria de Ciudad de Mexico, subvierte esta ideologia y sufre los estragos de una sociedad capitalista en ciernes al metaforizar corrupcion y transformacion de Ciudad de Mexico del Porfiriato. Este se nutrio de los ideales utopicos coloniales y se propuso abrir el pais a las inversiones extranjeras y al progreso. Gamboa coloca a Santa en el tiempo presente y pasado de ideologia colonial y eclesiastica que, a raiz sobre todo de aparicion guadalupana en 1531, busco evangelizar las tierras de Nueva Espana y en especial Ciudad de Mexico con los dictados del pensamiento utopico renacentista. | F8: 2014.0 | G8: 2014-11-27 | I8: VALID_TARGET_REFERENCE | J8: HIGH | K8: DIRECT_TARGET_REFERENCE | M8: OABASEV1_089588d91e7b4ae8 | N8: W000009285 | O8: W1415955523
A9: 4 | B9: A Clergyman's Daughter | C9: George Orwell | D9: The lasting in the ephemeral: assessing George Orwell’s As I Please columns | E9: George Orwell, author of the world famous Animal Farm (1945) and Nineteen Eighty-Four (1949), was also one of the greatest journalists of the last century. Born Eric Arthur Blair in Motihari, Bengal, in 1903, he won a scholarship to Eton but in 1921 left the college 138th out of 167 candidates in final-year exams. Confounding the expectations of his family, he sailed for Rangoon, Burma, to become a probationary assistant district superintendent of the Imperial Police. But he grew disillusioned with British imperialism and in 1927 resigned ‘on medical grounds’. That winter he went ‘down and out’ in London’s East End and the following year moved to a cheap hotel in Paris. He adopted the pseudonym George Orwell in November 1932, and Down and Out in Paris and London was published during the following year. The novels Burmese Days (1935), A Clergyman’s Daughter (1935) and Keep the Aspidistra Flying (1936) followed in quick succession. In 1936 he travelled through northern England, the West Midlands, Lancashire and Yorkshire researching the working class, and in December delivered the manuscript of The Road to Wigan Pier before leaving for Spain, which was in the grip of civil war. Here he fought for the Republicans against the fascists led by General Franco and was wounded, his experiences (and his conversion to socialism) being captured in Homage to Catalonia (1938). After two unhappy years working for the BBC’s Eastern Service, in February 1943 he became literary editor of Tribune, writing the weekly As I Please column. In 1945 he served as a war correspondent on the Continent for David Astor’s Observer. The same year also saw the publication of Animal Farm, which secured massive sales in Britain and the United States, and he began spending part of every 12 months in a cottage on the remote Scottish island of Jura, Inner Hebrides. While his health continued to deteriorate he worked on completing Nineteen Eighty-Four. He died in 1950 aged just 46, soon after marrying his second wife, Sonia. | F9: 2007.0 | G9: 2007-09-14 | H9: https://doi.org/10.4324/9780203939765-12 | I9: VALID_TARGET_REFERENCE | J9: HIGH | K9: DIRECT_TARGET_REFERENCE | L9: 書誌的な簡潔な言及（刊行年付き） | M9: OABASEV1_e8ef18a38ee80227 | N9: W000001625 | O9: W2282398063
A10: 5 | B10: Galen | C10: Galen | D10: Cerebral Venous Thrombosis Associated with COVID-19 | E10: Despite the severity of coronavirus disease 2019 (COVID-19) being more frequently related to acute respiratory distress syndrome and acute cardiac and renal injuries, thromboembolic events have been increasingly reported. We report a unique series of young patients with COVID-19 presenting with cerebral venous system thrombosis. Three patients younger than 41 years of age with confirmed Severe Acute Respiratory Syndrome coronavirus 2 (SARS-Cov-2) infection had neurologic findings related to cerebral venous thrombosis. They were admitted during the short period of 10 days between March and April 2020 and were managed in an academic institution in a large city. One patient had thrombosis in both the superficial and deep systems; another had involvement of the straight sinus, vein of Galen, and internal cerebral veins; and a third patient had thrombosis of the deep medullary veins. Two patients presented with hemorrhagic venous infarcts. The median time from COVID-19 symptoms to a thrombotic event was 7 days (range, 2-7 days). One patient was diagnosed with new-onset diabetic ketoacidosis, and another one used oral contraceptive pills. Two patients were managed with both hydroxychloroquine and azithromycin; one was treated with lopinavir-ritonavir. All patients had a fatal outcome. Severe and potentially fatal deep cerebral thrombosis may complicate the initial clinical presentation of COVID-19. We urge awareness of this atypical manifestation. | F10: 2020.0 | G10: 2020-05-20 | H10: https://doi.org/10.3174/ajnr.a6644 | I10: INVALID_TARGET_REFERENCE | J10: HIGH | K10: GENERIC_OR_LEXICAL_TITLE_USE | L10: "vein of Galen"（解剖学上の名祖）。著作への参照ではない | M10: OABASEV1_1dfbbf947e5898cd | N10: W000031472 | O10: W3027462748
A11: 6 | B11: Marie de France | C11: Marie de France | D11: Arthurian Literature by Women ed. by Alan Lupack and Barbara Tepa Lupack (review) | E11: REVIEWS115 scriptural exegesis. The author's appreciation for the Anglo-Saxon poet and his craft is everywhere palpable. Yet this is no blind admiration, but rather a feeling that has grown over many years of teaching and writing, reflecting on the nature of artistic creation and the deep meaning of the words of Beowulf. LEO CARRUTHF.RS Université de Paris-Sorbonne alan lupack and barbara tepa lupack, eds., Arthurian Literature by Women. Garland Reference Library of the Humanities 2137. New York: Garland, 1999. Pp. xiii, 382. isbn: 0-8153-3305-6 (hbk); 0-8153-3483-4 (pbk). $19.95. This anthology emphasizes Arthurian works by nineteenth- and twentieth-century women authors, although it also includes Marie de France's two Arthurian lais (twelfth century) and Lady Charlotte Guest's 1849 translation ofthe medieval Welsh tale, 'The Lady ofthe Fountain.' The intended audience for the collection is explicitly one already familiar with the writing ofsuch modern women writers ofArthurian subjects as Vera Chapman, Mary Stewart, Rosemary Sutcliff, Jane Yolen, Katherine Paterson, Fay Sampson, Gillian Bradshaw, Persia Woolley, and Marion Zimmer Bradley, and their writing is thus not represented. In fact, the names of the great majority ofwriters in Arthurian Literature by Women will probably be unfamiliar to all but zealous Arthurianists, preferably with access to works long out ofprint. This is as the editors have anticipated, however, for they hope 'to explore that rich but forgotten tradition' (xi), a phrase that in part provides the title oftheir introduction. The earliest modern work reprinted hete is Anne Bannerman's 'The Prophecy of Merlin' (1802), followed by Letitia Elizabeth Landon's A Legend ofTintagel Castle' (1833) and the anonymous—the author signs merely as a 'daughter of Eve'—'The YIIe Cut Manteir (1844), a story that can be traced to the Middle Ages. Thirteen other works date from the second halfofthe nineteenth century. To note just three: the selections by Elizabeth Stuart Phelps re-create Galahad, Elaine/The Lady of Shalott, and Guenevere as poor folk living in 'realistic' squalor, presented with the heightened pathos such a setting can allow; Dinah Maria Mulock Craik's Avillion; Or, the Happy Isles features the enfeebled Wilfred Mayer and his devoted wife Lilias Hay; their encounter, during a sea voyage, with a German physician and his magic medicine sends Mayer into a lengthy but curative dream that includes both Greek mythological and Arthurian personae; and the scholar Jessie Weston is represented by a poem, 'Knights of King Arthur's Court,' written in 1896. A concentration ofselections from the period between 1901-1931 includes Martha Kinross's much-admired drama 'Tristram and Isoult,' two poems by Sara Teasdale, Edna St. Vincent Millay's 'Elaine,' and Dorothy Parker's 'Guinevere at Her Fireside' and 'Iseult of Brittany.' Conceivably less known are the short poems by Grace Constant Lounsbery, Sophie Jewett, Helen Hay Whitney, Elizabeth Colwell, and Aline Kilmer. Annie Fellows Johnston's prose tale, 'Keeping Tryst: ATaIe of King Arthur's Time,' is a children's story (but there is nothing new in the blurring of borders in much modern Arthurian composition between stories for children or Il6ARTHURIANA young adults and those for older readers). Two selections, Valerie Nieman's intriguing 'The Naming of the Lost' (1989) and four Guenevere poems by Wendy Mnookin (1991) close the volume. Readers will appreciate the generous number of works that this anthology provides, as well as the valuable service it performs by making available otherwise hard-to-get writing. A spot check of selections against first editions inspires confidence in the editors' care in transcription. Some aspects ofpresentation, however, may prove baffling. For editors, choosing from an array of material is always a daunting task, and focusing on the worthybut -forgotten is an unimpeachable aim. But it is surprising to read that Marie de France's 'Lanval' (with all due respect for Norris Lacy's translation) or 'The Lady of the Fountain' are forgotten, given that they are available elsewhere in inexpensive editions (a translation of 'Lanval' is even posted on the Net) and often used in college courses. Similarly, Wendy Mnookin's poetry, composed within the last decade, isn't old enough to have been forgotten, nor indeed is it... | F11: 2000.0 | G11: 2000-06-01 | H11: https://doi.org/10.1353/art.2000.0018 | I11: VALID_TARGET_REFERENCE | J11: HIGH | K11: DIRECT_TARGET_REFERENCE | L11: Marie de FranceのLanval等アーサー王レーを収録・論評 | M11: OABASEV1_40bebf73fdd0df4a | N11: W000000860 | O11: W2023772851
A12: 7 | B12: Edgar Allan Poe | C12: Edgar Allan Poe | D12: Padre Brown e Chesterton | E12: Este artigo propõe uma análise dos romances policiais de G. K. Chesterton, com ênfase no personagem Padre Brown, em diálogo com a história do gênero policial e seu contexto social. A partir da reflexão de Borges, que posiciona Chesterton como herdeiro de Edgar Allan Poe por unir elementos fantásticos a soluções racionais, discutimos como suas narrativas policiais interagem com o surgimento da polícia moderna. Neste percurso, autores como Todorov, Carpeaux e Ortega y Gasset são referências para pensar a história do romance policial e a sua relação com a sociedade. Com base nas reflexões propostas neste artigo, conclui-se que Chesterton oferece uma crítica à modernidade, não como uma decadência, mas como uma condição a ser desafiada, evocando um perfil quixotesco diante do mundo moderno. | F12: 2025.0 | G12: 2025-08-02 | H12: https://doi.org/10.12660/rm.v17n27.2025.93039 | I12: VALID_TARGET_REFERENCE | J12: MEDIUM | K12: VALID_CONTEXTUAL_REFERENCE | L12: 著者名ターゲット：Chestertonを「Poeの後継者」とする文学史的言及のみ | M12: OABASEV1_8637292cb4dcfc72 | N12: W000018534 | O12: W4415819236
A13: 8 | B13: Heart of Darkness | C13: Joseph Conrad | D13: Jack London's Heart of Darkness | E13: ALTHOUGH there are certain obvious similarities in the fiction of Jack London and Joseph Conrad-both wrote tales of the sea well stories set in exotic lands, and frequently both peopled their fiction with rough characters engaged in violent action-Conrad's different emphasis, surer craftsmanship and more profound insight into the psychological motivations of his characters have made these similarities seem relatively inconsequential. London is often, even within the same book, an exponent of the cult of raw meat and red blood and a political expounder using fiction a means of advancing the doctrines of socialism. This blatant dichotomy is in obvious contrast to Conrad's characteristically subtle investigations of states of mind. Conrad himself bridled at being regarded as literarily a sort of Jack London: | F13: 1958.0 | G13: 1958-01-01 | H13: https://doi.org/10.2307/2710175 | I13: VALID_TARGET_REFERENCE | J13: HIGH | K13: VALID_CONTEXTUAL_REFERENCE | L13: 題名がConradの作品を援用し、本文でもConradを比較対象として扱う | M13: OABASEV1_949e657f2edb4f91 | N13: W000014272 | O13: W2313439067
A14: 9 | B14: The Road | C14: Jack London | D14: Jack London by Kenneth K. Brandt | E14: Reviewed by: Jack London by Kenneth K. Brandt Earle Labor Kenneth K. Brandt, Jack London. Liverpool: Liverpool UP, 2018. 149 pp. Cloth, $80; paper, $29.95. "Multum in Parvo" would be an appropriate title for this review. Seldom have I read a scholarly book that provided so much useful content in so few pages. In view of Kenneth Brandt's established position in the world of Jack London, I'm hardly surprised: executive coordinator of the Jack London Society and editor of The Call, the Society's official magazine; coeditor (with Jeanne C. Reesman) of Approaches to Teaching the Works of Jack London (2015); plus multiple shorter publications. Brandt states his approach in his opening chapter: "My study challenges the unexamined assumption that London's narrative accessibility consigns his work to thematic simplicity" (2). The following six chapters examine the extraordinary range of London's fiction from the Northland to the South Pacific with significant thematic variations in between: London's world-famous dystopian novel The Iron Heel, plus shorter Socialistic works like "Goliah" and "The Strength of the Strong"; the tragic consequences of "Individualism" in The Sea-Wolf and Martin Eden; the "compatibilistic" resolution of free will vs. determinism in The Road and The Star Rover. While selective rather than exhaustive, the representative works Brandt examines are truly exemplary. Beyond devoting considerable attention to popular novels like The Call of the Wild, White Fang, and The Sea-Wolf, he also includes careful readings of less-familiar works [End Page 452] like "Nam-Bok the Unveracious," "The Night-Born," "The House of Pride," "Mauki," "The Red One," and "The Water Baby." These last two stories are particularly noteworthy. Written during a period many critics have dismissed as creatively arid, they demonstrate the rich stylistic as well as thematic diversity of London's oeuvre. Brandt points out that while London was "adept at spinning a good yarn, [he] deliberately layered his fiction [and] ballasted his best stories with heftier motifs expressive of profounder implications" (15). Virtually unknown even by London fans for more than a half century, "The Red One" is arguably the most richly layered of all his stories. On one level it is an adventure tale about a modern scientist exploring the terra incognita of one of the Solomon Islands. Beneath this is the mystery of a sentient object apparently planted by some extraterrestrial force (think of Stanley Kubrick's 2001: A Space Odyssey). Deeper still, it dramatizes the universal human quest for the ultimate "Self" and "Truth." Finally, with its "wealth of allusions to the Bible and Greek mythology and English poetry," the story is comparable to T. S. Eliot's The Waste Land in suggesting "a viable repository of cultural knowledge that may serve to mitigate modernity's malaise" (120). "The Water Baby"—written shortly after his discovering C. G. Jung and less than two months before his death—is one of London's most revealing stories. Unlike most of his fiction, the physical action is minimal. Instead, tension is derived from a dialogue between two characters: John Lakana (London's Hawaiian name) and Kohokumu (Hawaiian for "tree of knowledge"). Lakana, a young Caucasian, as Brandt notes, "exemplifies Western rationality and the exhaustion of modernity" (121). Kohokumu, personifying Jung's archetypal figure of the Wise Old Man, is "an ebullient septuagenarian fully vitalized by the myth and lore of his native culture." In their argument, the elder character convincingly demonstrates that inner Truth transcends mere external Fact. "This I know," he tells Lakana, "as I grow old I seek less from the truth from without me, and find more of the truth from within me" (121). This remarkable story, his last, is eloquent testimony that London—ever the "seeker"—was still adventuring as he himself grew old. [End Page 453] Throughout this critical study Brandt undergirds his own interpretive insights with references to other significant scholarly works. The final chapter, "Coda: Literary Legacy and Scholarship"—surveying the growth of serious London scholarship during the past generation—effectively corrects the distorted image of a hack writer who made his fortune by commercializing popular dog stories. Contrary to this stereotype, London's international status as "a prominent writer and... | F14: 2020.0 | G14: 2020-01-01 | H14: https://doi.org/10.1353/wal.2020.0008 | I14: VALID_TARGET_REFERENCE | J14: HIGH | K14: DIRECT_TARGET_REFERENCE | M14: OABASEV1_edb5f6c48b0acfd7 | N14: W000026722 | O14: W3005009023
A15: 10 | B15: Galen | C15: Galen | D15: Greek Science - The Heart and the Vascular System in Ancient Greek Medicine from Alcmaeon to Galen. By C. R. S. Harris. Oxford: Clarendon Press: Oxford University Press, 1973. Pp. x + 474. £15.00. | E15: Greek Science - The Heart and the Vascular System in Ancient Greek Medicine from Alcmaeon to Galen. By C. R. S. Harris. Oxford: Clarendon Press: Oxford University Press, 1973. Pp. x + 474. £15.00. - Volume 7 Issue 2 | F15: 1974.0 | G15: 1974-07-01 | H15: https://doi.org/10.1017/s0007087400013236 | I15: VALID_TARGET_REFERENCE | J15: MEDIUM | K15: VALID_CONTEXTUAL_REFERENCE | L15: 著者名ターゲット：医学史書の題名中でGalen（医学著作者）に言及 | M15: OABASEV1_a0a4a13f8c9ccd49 | N15: W000031472 | O15: W1965933617
A16: 11 | B16: Ulysses | C16: James Joyce | D16: Beyond Borders: I.A.S.I.L. Essays on Modern Irish Writing (review) | E16: Reviewed by: Beyond Borders: I.A.S.I.L. Essays on Modern Irish Writing Walter Corbella (bio) Beyond Borders: I.A.S.I.L. Essays On Modern Irish Writing, edited by Neil Sammells . Bath: Sulis Press, 2004. 281 pp. $44.95. As historians and critics have frequently noted, Ireland is a deeply divided nation. Geographical, political, religious, and social boundaries have defined the Irish ethos and left an indelible mark in the work of Irish authors. This sense of division has determined, in multiple ways, the fragmentation that recurs as thematic component and stylistic device in their fiction. Beyond Borders recaptures these notions of boundaries, borders, and limits, as well as the associated concepts of transgression, crossing, and disruption as the organizing principles for the sixteen essays that form this collection. In "The Victorian Celt Stereotyped, Historicized and Imagined," Simon Trezise offers a historical and literary perspective on the phenomenon of stereotype formation. Focusing on nineteenth-century views of the Celts, particularly those of John Beddoe and Sophie Bryant, Trezise analyzes the interrelations between scientific bias and stereotypes.1 In opposition to the pseudoscientific notions of the Celt, he exposes the historical factors which led to the emergence of the Irish Celt as necessary racial and religious Other, stressing the attempts to combat those stereotypical views during the Irish Literary [End Page 398] Renaissance. In J. M. Synge's work, Trezise finds a more genuine, yet unsentimentalized, view of the Irish that arises from actual observation of, and interaction with, the people.2 This piece prepares the ground for the two subsequent essays, both of which foreground the relation between Padraic Pearse and W. B. Yeats. "Yeats and Pearse in Dialogue," by Robert Tracy, reads the Proclamation of the Irish Republic as political document, literary work, and response to Yeats's play Cathleen ni Houlihan.3 According to Tracy, through his use of imagery and his dramatic reading of the Proclamation, Pearse established a dialogue with Yeats that the latter would acknowledge and continue in his poem "Easter, 1916."4 Paul Murphy's "Yeats, Pearse and the Sublime Subaltern" lays emphasis on the ambiguity of Cathleen ni Houlihan. The play lends itself to two competing interpretations, both of which rely on the subordination of the archetypal "peasant" to national and class interests. By contrast, in Pearse's play The Singer, the idealized peasant assumes "oxymoronic status as the sublime subaltern" (48), which conceals his subordination.5 In Murphy's view, these plays exemplify the distinct approaches of "Anglo-Irish" and "Irish-Irish" ideologies in postcolonial contexts. It is hard to imagine that a conference on, or overview of, Irish literature would fail to include Yeats and James Joyce, and the International Association for the Study of Irish Literatures' collection proves no exception. Ellen Carol Jones's "Joyce and Dividing Lines" and Louis Armand's "Joycean Hypertext: Technology and the Word in Finnegans Wake" approach Joyce's work from the perspective of postcolonial and postmodern theory respectively. Jones's somewhat obscure reading of the "Oxen of the Sun" episode in Ulysses explores the uses of language in the negotiation of identities through the production of "hybrid writing" in an "in-between space" (57). In such a space, the subaltern can engage in acts of translation, transgression, and transcription. In reference to the transgressive use of translation, Jones wonders, "How does cultural translation as a tropic movement transform the heliotropics of a dominant culture, the heliopolitics of imperialism?" (58). This type of "cultural translation," she argues, appears as pastiche in "Oxen of the Sun" and serves the purposes of interrogating and fragmenting the dominant cultural paradigms. At the same time, the creation of hybrid language and writing attests to the miscegenation resulting from imperialism. Having acknowledged Jacques Derrida's and Jean-Michel Rabaté's essays on Finnegans Wake, Armand characterizes Joyce's text as a language-producing machine.6 He claims, "The desiring machine, miming the totalizing movement of an exegesis, or exe-genesis, approaches a topological relation to itself similar to that of the Cantorean paradox of the set of all sets" (73-74). This statement illustrates the ways in which the complexities of Armand's prose complicate his interpretation of... | F16: 2007.0 | G16: 2007-10-21 | H16: https://doi.org/10.1353/jjq.2007.0029 | I16: VALID_TARGET_REFERENCE | J16: HIGH | K16: DIRECT_TARGET_REFERENCE | L16: Ulysses "Oxen of the Sun"エピソードの論評 | M16: OABASEV1_15a44f295ac4a304 | N16: W000016985 | O16: W2067893208
A17: 12 | B17: Henry James | C17: Henry James | D17: Theme and its Embadiment in the Works of Henry James | F17: 1984.0 | G17: 1984-05-01 | I17: VALID_TARGET_REFERENCE | J17: HIGH | K17: DIRECT_TARGET_REFERENCE | M17: OABASEV1_b85d6b77c16fdc95 | N17: W000014024 | O17: W2342413711
A18: 13 | B18: D.H. Lawrence | C18: D. H. Lawrence | D18: Cult of spontaneity : D. H. Lawrence and occult | F18: 2006.0 | G18: 2006-01-31 | I18: VALID_TARGET_REFERENCE | J18: HIGH | K18: DIRECT_TARGET_REFERENCE | M18: OABASEV1_c467d5285d646416 | N18: W000030498 | O18: W7208665622
A19: 14 | B19: Ulysses | C19: James Joyce | D19: Joyce among the Cockneys: The East End as Alternative London | E19: The first time James Joyce went to London, both Richard Ellmann and Gordon Bowker's biographies recount, was in May 1900 (jjii 77).1 As well as visiting relatives in East End of city with his father, Joyce sampled all usual delights of cosmopolitan town. As Bowker puts it, John Joyce [showed] his son how to enjoy London - visiting music-halls, theatres, pubs and restaurants.2 It is difficult to ascertain exactly what entertainment young Joyce saw on his trip, but in any case, his being enamoured with halls in particular was clear: upon his return, Joyce would write to his brother Stanislaus proclaiming that the music hall, not poetry, is a criticism of life (jjii 77).With a series of cities already closely associated with author's writing - Dublin and Ulysses-closing Trieste-Zurich-Paris (u 993) - London has hitherto been a somewhat neglected locale in Joyce scholarship. Despite city making repeated appearances in Joyce's works following his 1900 visit, it is only recently that scholars have been encouraged to look towards London, prompted by a broader spatial turn in field. While such studies are welcome, their focus is still relatively narrow in scope. As first metropolis in an empire which included Ireland until 1922, London features most frequently in Joyce criticism as administrative colonial centre. While this interpretation allows significant insight into one facet of capital, it necessarily fails to account for intra-city local differentiation to which Joyce was attuned - homogenising, as it must, London as empire's synecdoche, or at least its symbolic geopolitical centre. The portrait of London in Joyce's novels and poetry, however, is attentive to varying characteristics of city's districts. Indeed, rather than simply rail against empire's heart, it is precisely London's multifaceted nature which Joyce employs to subvert its power as staid colonial centre, using East End of city as a disruptive counterpoint to its supposed propriety and authority.It is, of course, impossible to tell how seriously Joyce intended his line to Stanislaus on music hall to be taken. Yet, whether he meant its elevation above poetry earnestly or ironically, two inferences from Joyce's statement might productively frame his subsequent engagement with East End. The first is concept of hall as an alternative. Juxtaposed against poetry, Joyce proposes music hall as an art form distinguished from more established and, we can reasonably assume, more conventional traditions. The second is music hall as a form able to speak critically of life. Not simply a diversion or play, Joyce here entertains halls as a space in which culture might be assessed and criticised. In what follows, I will suggest that vaudeville East End represented in music hall came to serve this function in Joyce's writing. Contrary to versions of East End which we might expect to find in his works - on which more in a moment - Joyce employs a Cockneyism set against more conservative depictions of city-as-a-whole. A thorough knowledge of area allowed Joyce to selectively contrast tropes and images of East End with their orthodox London counterparts, whether it be in placing ribald Cockney women alongside less locally-inflected British ones, using East End humour to make dignified images of London bathetically ludicrous, or aligning area with other foreign spaces. Tracing use of East End slang, place names, and figures in Dubliners (1914), Ulysses (1922), Finnegans Wake (1939), and Joyce's poetry, this essay will demonstrate how Joyce thus used aesthetic of music hall to fashion a destabilising alternative to London's imperial power.Joyce's general interest in East End is suggested via even most cursory examination of area's fragmented iterations in Finnegans Wake. Numerous appearances of Bow Bells (fw 626. … | F19: 2016.0 | G19: 2016-01-01 | H19: https://doi.org/10.1163/9789004314467_007 | I19: VALID_TARGET_REFERENCE | J19: HIGH | K19: DIRECT_TARGET_REFERENCE | M19: OABASEV1_497d0fea9df9d4ca | N19: W000017666 | O19: W2486871367
A20: 15 | B20: Lamb | C20: Charles Lamb | D20: The portable Charles Lamb | E20: One of the volumes in the distinguished Viking Portable series, this portable carries selections from Lamb's letters, essays, fantasies, poetry and criticism. | F20: 1949.0 | G20: 1949-01-01 | I20: VALID_TARGET_REFERENCE | J20: HIGH | K20: DIRECT_TARGET_REFERENCE | M20: OABASEV1_bc86df8c044a6e1e | N20: W000020329 | O20: W1605818641
A21: 16 | B21: Gray | C21: Thomas Gray | D21: The Magazine of Magazines, September 1756 | E21: Front and back covers and pages from The Magazine of Magazines bound collection. In 1751, Limerick printer Andrew Welsh began printing an edition of the London based The Magazine of Magazines. Welsh, having learnt his trade from his father in Cork, began printing the Magazine, based in a building called ‘The Exchange’ on Nicholas Street, Englishtown, near the cathedral in Limerick. The Limerick publication started life as a direct, almost page for page, reprint of the London edition, printed by William Owen. The publication was a major undertaking for Welsh in Limerick. Welsh claims to have bought an entirely new set of type dedicated to printing the magazine, and the Limerick edition (like many other Irish re-prints of English works) is of better quality than its London counterpart. The Limerick edition was not simply aimed at the immediate urban public; there are three named retailers in Cork as well as one in Dublin. The Magazine, which was published for the best part of two decades, from 1751 to 1769, is a miscellany comprising of extracts from numerous eighteenth century periodicals and journals and covers subjects as diverse as Science, Philosophy, Medicine, Meteorology, Religion, Mythology and Literature to name but a few. It was the first periodical publication to feature Thomas Gray’s famous Elegy Written in a Country Churchyard, in 1751, and published essays and excerpts from towering intellectual figures of the day such as Dr Johnson and Voltaire. Prof Geraldine Sheridan, Dr. Michael Griffin, Yvonne Diggins, Research Assistant. | F21: 2011.0 | G21: 2011-03-08 | I21: VALID_TARGET_REFERENCE | J21: HIGH | K21: DIRECT_TARGET_REFERENCE | L21: Grayの「Elegy」初掲載への言及 | M21: OABASEV1_dfe983daadb4f360 | N21: W000030513 | O21: W7209637656
A22: 17 | B22: Galen | C22: Galen | D22: 6 THE LONG SHADOW OF ANTIQUITY MEDICINE AND PLANTS | E22: The practice of using plants for medical treatment is as old as is mankind.Classical sources (by Dioscorides, Pliny, and Apuleius Platonicus, as well as the theory of humours by Galen) formed the basis for medieval healthcare.The Hippocratic oath (c.fourth century BC) is the earliest expression of medical ethics.Although some medieval recipes are not advisable, others are: people knew the healing potency of hypericum, but were also aware of the poisonous power of hemlock.The quadripartite periodization -monastic medicine / Salernitan medicine / the rise of the universities / scholastic medicine -is based on the relationship of texts to their Greco-Roman sources.Medieval writings like those of Hildegard von Bingen and local vernacular sources were popular in their own time. | F22: 2023.0 | G22: 2023-04-25 | H22: https://doi.org/10.1515/9789048557745-008 | I22: VALID_TARGET_REFERENCE | J22: MEDIUM | K22: VALID_CONTEXTUAL_REFERENCE | L22: 著者名ターゲット：Galenの体液説（著作内容）への言及 | M22: OABASEV1_51dcbfd4a7a824da | N22: W000031472 | O22: W4366994716
A23: 18 | B23: Galen | C23: Galen | D23: Fraeisam Büchlein Petri Hofmanns von d. Praeservation u. Curation d. Fräisams oder Epilepsia an kleinen Kindern, auff Galen. u. Paracels. Art | I23: VALID_TARGET_REFERENCE | J23: MEDIUM | K23: VALID_CONTEXTUAL_REFERENCE | L23: 著者名ターゲット：「auff Galen. u. Paracels. Art」ガレノス流医学への言及 | M23: OABASEV1_d06095b070a8be87 | N23: W000031472 | O23: W7056805148
A24: 19 | B24: Arnold | C24: Matthew Arnold | D24: The Darkening Age: The Christian Destruction of the Classical World. By Catherine Nixey | E24: Pivoting on the vagaries of Late Antiquity, The Darkening Age presents a tendentious, unflinching narrative of how Classical art and literature were systematically obliterated by the Christian movement. Catherine Nixey tracks Christianity’s trail of terror, crisscrossed through time and space. She exposes the presumed smooth denunciation of polytheistic culture as Christian fabrication. This is a book of watershed moments and snapshots of everyday life. It is not a scholastically-encumbered historical narrative but a widely accessible kind of ‘historical travelogue’ (p. xxxv). Nixey builds her account on a wealth of first-hand documents, such as official epistles and polemical diatribes cited discreetly in the book’s back matter. Apposite literary references such as Matthew Arnold’s ‘Dover Beach’ (p. 23) and Umberto Eco’s The Name of the Rose (p.139) enrich the discussion. The structure is circular, beginning and ending with the last Neoplatonist philosopher Damascius of the Athens Academy, which was proscribed by Emperor... | F24: 2020.0 | G24: 2020-07-03 | H24: https://doi.org/10.1093/litthe/fraa014 | I24: VALID_TARGET_REFERENCE | J24: HIGH | K24: DIRECT_TARGET_REFERENCE | L24: Arnoldの「Dover Beach」引用 | M24: OABASEV1_b974cf40325ffbf7 | N24: W000003023 | O24: W3082104555
A25: 20 | B25: Alice in Wonderland | C25: Lewis Carroll | D25: alicia en el pais de las adivinanzas pdf | E25: alicia en el pais de las adivinanzas pdf Rating: 4.4 / 5 (3179 votes) Downloads: 46426 = = = = = CLICK HERE TO DOWNLOAD = = = = = Así pues, el Rey y el verdugo empezaron a corretear de un lado a otro en busca del Gato, mientras el resto del grupo volvía a la partida de croquet alicia-en-el-pais-de-las-adivinanzas-un-cuento-alDownloaded from on by guest bibliotecadigitalilceedumx capítuloen la madriguera del conejo Con hermosas ilustraciones, el Ejército Nacional presenta en la Feria Internacional del Libro de Bogotá, Filbo, un libro, como una la guía pedagógica Missing: pdf · Ciudad de México,abr (EFE) La candidata presidencial del oficialismo mexicano, Claudia Sheinbaum, anticipó este miércoles que durante el segundo debate Missing: pdf Seleccione una colección (fáciles, difíciles, cortas, animales, frutas, niños, etc.) de adivinanzas para descargar e imprimir. Cada PDF tiene tanto las adivinanzas como sus respuestasintroduce al lector en los conceptos básicos del enfoque de los estudios literarios, y analiza la ironía, la parodia, el pastiche, el kitsch, la metaficción, la intertextualidad, el sinsentido y la sátira, entre algunas de las estrategias que quedan al descubierto en la literatura infantil contemporánea La cabeza del Gato empezó a desvanecerse a partir del momento en que el verdugo se fue, y, cuando éste volvió con la Duquesa, había desaparecido totalmente. introduce al lector en los conceptos básicos del enfoque de los estudios literarios, y analiza la ironía, la parodia, el pastiche, el kitsch, la metaficción, la intertextualidad, el sinsentido Alicia en el país de las adivinanzas Raymond Smullyan AtrapalecturasCecilia Beuchat Cecilia Beuchat invita a los niños y niñas a conocer la Resumen y sinopsis de Alicia en el país de las adivinanzas de Raymond Smullyan Raymond Smullyan, lógico, matemático, filósofo, mago y humorista, domina Parodiando el estilo de Lewis Carroll, la Tortuga y el Grifo, el par de gemelos Tweedledee y Tweedledum, los Reyes de Corazones, el pedante huevo Humpty Dumpty y el Caballero Alicia en el país de las adivinanzas Raymond Smullyan Alice in Wonderland Nadia Fabris,Irena Trevisan Lewis Carrolls Alice in Wonderland is retold in this Sinopsis. Raymond Smullyan, lógico, matemático, filósofo, mago y humorista, domina genialmente el arte de plantear con divertidos acertijos arduos problemas de Alicia en el país de las adivinanzas Raymond Smullyan alicia-en-el-pais-de-las-adivinanzas-un-cuento-alDownloaded from on · Comentar. | F25: 2024.0 | G25: 2024-06-10 | H25: https://doi.org/10.5281/zenodo.12270814 | I25: VALID_TARGET_REFERENCE | J25: MEDIUM | K25: VALID_CONTEXTUAL_REFERENCE | L25: スパム的集約テキストだが「Lewis Carrolls Alice in Wonderland」を明示（Smullyanのパロディ紹介文中） | M25: OABASEV1_6528933d9cba7dd6 | N25: W000018284 | O25: W6892801732
A26: 21 | B26: Gray | C26: Thomas Gray | D26: Thomas Gray to Horace Walpole, 4th earl of Orford, Monday, 31 March 1738 [graythOU0010082a1c] | F26: 2014.0 | G26: 2014-07-31 | H26: https://doi.org/10.13051/ee:doc/graythou0010082a1c | I26: VALID_TARGET_REFERENCE | J26: HIGH | K26: DIRECT_TARGET_REFERENCE | L26: 著者名ターゲット：Gray自身の書簡（一次資料） | M26: OABASEV1_d46dfe6be8c6e04c | N26: W000030513 | O26: W4232127913
A27: 22 | B27: Dom Juan | C27: Molière | D27: Dom Juan, Molière, Acte III Scène 4 | F27: 2012.0 | G27: 2012-11-21 | I27: VALID_TARGET_REFERENCE | J27: HIGH | K27: DIRECT_TARGET_REFERENCE | M27: OABASEV1_16de529922e8392f | N27: W000030756 | O27: W18873569
A28: 23 | B28: Louisa May Alcott | C28: Louisa May Alcott | D28: Resumen de tesis. Challenging gender roles in Austen's Pride and Prejudice and Alcott's Little Women and their reception. A comparative study | E28: [ES] Jane Austen es considerada una de las escritoras mas importantes de la historia de la literatura. Desde la publicacion de su primera novela en 1811 hasta las ultimas adaptaciones cinematograficas de sus obras, Austen se ha convertido en un fenomeno mundial. Es casi imposible encontrar a alguien que no haya oido hablar de Jane Austen ya sea por sus novelas o por una de las muchas adaptaciones de sus obras a la pequena o gran pantalla. Por su parte, Louisa May Alcott tambien se convirtio en una escritora muy conocida gracias a su trilogia de Mujercitas; sin embargo, nunca fue tan popular como Jane Austen, especialmente en el mundo academico. A pesar de las aparentes diferencias, es posible establecer paralelismos entre las circunstancias de las autoras, su recepcion y su reciente ascenso a la fama dentro de la cultura popular. Aunque estas novelistas se encuentran separadas por el Oceano Atlantico y mas de medio siglo, como escritoras se enfrentaron a dificultades similares y abordaron experiencias feminocentricas recurrentes, mientras que sus obras fueron elogiadas y criticadas casi por igual. Sin embargo, la investigacion ha demostrado que no existen estudios comparativos exhaustivos que aborden estas similitudes. Para llenar este vacio, la presente tesis ha sido concebida con los siguientes objetivos: primero, exponer como sus trabajos mas conocidos muestran preocupaciones similares con respecto a las mujeres y como a lo largo del tiempo se perciben algunos avances en sus derechos; en segundo lugar, explorar como su sexo y los generos literarios que eligieron han definido su recepcion a lo largo del tiempo, lo que demuestra ciertos prejuicios en criticos y lectores; y, finalmente, analizar las razones de la popularidad actual y como las nuevas adaptaciones simplifican de manera similar sus trabajos. | F28: 2019.0 | G28: 2019-01-01 | I28: VALID_TARGET_REFERENCE | J28: HIGH | K28: DIRECT_TARGET_REFERENCE | L28: Little Women（Mujercitas）を扱う | M28: OABASEV1_6be9aeab4d0f0b65 | N28: W000014515 | O28: W3006176929
A29: 24 | B29: The Ambassadors | C29: Henry James | D29: Representações da descoberta: espaço e epifania em The ambassadors | E29: The aim of this paper is to analyze how the novel The ambassadors, published in 1903 by the American author Henry James (1843-1916), relates the narrative category of space to Lewis Lambert Strether’s epiphany based on some literary concepts conceived by Osman Lins (1976), Iuri Lotman (1978) and James Joyce (1963). We will attempt to show in what manner the revelation of truth is connected to the external space illuminated by the natural light of an inn, conveniently named Cheval Blanc, and harmonizes with the steps of the epiphanic process (integrity, symmetry and radiance), promoting Strether’s self-consciousness. | F29: 2013.0 | G29: 2013-01-01 | I29: VALID_TARGET_REFERENCE | J29: HIGH | K29: DIRECT_TARGET_REFERENCE | M29: OABASEV1_c46b7a49f5544dc5 | N29: W000014023 | O29: W2616175040
A30: 25 | B30: Charles Lamb | C30: Charles Lamb | D30: S imon P. H ull , Charles Lamb, Elia and the London Magazine (London: Pickering & Chatto, 2010), pp. 240. £60 / US $99 hardback. 9781851966615. | F30: 2011.0 | G30: 2011-10-01 | H30: https://doi.org/10.3366/rom.2011.0055 | I30: VALID_TARGET_REFERENCE | J30: HIGH | K30: DIRECT_TARGET_REFERENCE | M30: OABASEV1_f709119bfad1d258 | N30: W000020297 | O30: W2077889046

Sheet Audit 02
A1: OpenAlex R2+A1 Blind Human Audit — R2A1A02
A2: 判定対象：OpenAlex record が target literary work を本当に参照しているか。LLM判定・sampling stratum・risk featureは非表示です。Web検索はしません。
A4: 入力欄 → | I4: Judgment | J4: Confidence | K4: Reason | L4: Reviewer note
A5: Review # | B5: Target title | C5: Target author | D5: OpenAlex record title | E5: OpenAlex abstract | F5: Year | G5: Publication date | H5: DOI | I5: Judgment | J5: Confidence | K5: Reason | L5: Reviewer note | M5: Candidate ID | N5: Project Work ID | O5: OpenAlex Work ID
A6: 26 | B6: Galen | C6: Galen | D6: Prenatal Diagnosis of the Aneurysm of the Vein of Galen by Pulsed Doppler Unit | E6: Aneurysm of the vein of Galen is a rare anomaly. In the severe type, the first clinical manifestation of this anomaly is heart failure after birth. Prenatal diagnosis is important in preventing heart failure during the postnatal period. Here, we report the prenatal diagnosis of a case of aneurysm of the vein of Galen in which we used a pulsed Doppler unit combined with a fetal electrocardiogram-phonocardiogram unit. | F6: 1991.0 | G6: 1991-07-01 | H6: https://doi.org/10.1055/s-2007-999388 | I6: INVALID_TARGET_REFERENCE | J6: HIGH | K6: GENERIC_OR_LEXICAL_TITLE_USE | L6: "vein of Galen"（解剖学上の名祖） | M6: OABASEV1_ffd1703fe30fa950 | N6: W000031472 | O6: W2081917034
A7: 27 | B7: Edgar Allan Poe | C7: Edgar Allan Poe | D7: The Grotesque Elements in Poe’s “Black Cat” and Scudder’s “The White Cat” | E7: The present essay focuses on the grotesque elements in Edgar Allan Poe’s the “Black Cat” and Horace Scudder’s “The White Cat”. Poe’s story is highly embedded with a lot of grotesque elements from the beginning to the end. These elements were presented through strange characters, mysterious happenings, and degradation through death. Poe represents the struggle between the supernatural and the natural which he reinforces through the narrator who struggles to commit wrongdoings. Even in the mist of trying to restrict himself, the narrator still does not know what he did. In “The White Cat,” Scudder employs grotesque elements as well but his application is subtly done unlike Poe whose application is more pronounced. The underlying meaning of this short story is on the spell of enchantment. However, Scudder, like Poe, displays the supernatural events through the characters of the “fairies” who has magical power to change the once a beautiful princess to a white cat. Grotesque includes absurd and bizarre elements and pierces the conventional version of reality. However; in its ability to shock or offend, grotesque helps to expose the vulnerability in human depicted via these absurd element which will be explained in detail in the present study. | F7: 2014.0 | G7: 2014-04-26 | H7: https://doi.org/10.7575/aiac.ijclts.v.2n.2p.42 | I7: VALID_TARGET_REFERENCE | J7: HIGH | K7: DIRECT_TARGET_REFERENCE | M7: OABASEV1_3872a4b2d4dd6dda | N7: W000018534 | O7: W2115502554
A8: 28 | B8: Petronius | C8: Petronius | D8: Petronius és Martialis simplicitas-a | F8: 1947.0 | G8: 1947-01-01 | I8: VALID_TARGET_REFERENCE | J8: HIGH | K8: DIRECT_TARGET_REFERENCE | L8: 著者名ターゲット：Petroniusの文体論 | M8: OABASEV1_e4cc3877ebf1ff31 | N8: W000021772 | O8: W7042323523
A9: 29 | B9: The Hobbit | C9: J.R.R. Tolkien | D9: Paisajes de Tolkien en la Tierra Media. | E9: El artículo reflexiona sobre la carga simbólica y emocional de los dos tipos de escenarios paisajísticos muy marcados y diferenciados que aparecen en la trilogía cinematográfica de “El Hobbit” (The Hobbit) (2012, 2013, 2014), de Peter Jackson.Uno de los paisajes será armónico, tranquilo, edénico y de luz, donde todo funciona en sociedades ideales que habitan criaturas antropomórficos de buena voluntad e intención como son los hobbits y los elfos, mientras que el otro paisaje será oscuro y desolador habitado por seres terroríficos como trasgos y orcos, dominados por una fuerza misteriosa de siniestro poder llamada el Nigromante que siembra el mal en su sombrío territorio. A través del universo creado por el escritor y profesor J.R.R.Tolkien y de su imaginaria y fascinante Tierra Media, se analiza el escenario paisajístico cinematográfico intentando buscar las claves que lo definan a medida que es recorrido por la comunidad formada por el mago Gandalf el Gris, (Ian McKellen),el hobbit Bilbo Bolsón, (Martin Freeman), el rey enano Thorin Escudo de roble (Richard Armitage) y los otros doce enanos que le acompañan, partiendo del paisaje edénico de la Comarca y del armonioso y casi perfecto Rivendel, pasando por las tierras siniestras y de penumbra donde el paisaje aparece muy en consonancia con la obra de pintores y grabadores del romanticismo como Piranesi o Caspar David Friedrich, cuyas obras se reflejan a la perfección en el Bosque de Trolls, Dol Guldur en el Bosque Negro, y la Ciudad de los Trasgos en busca del antiguo reino de los enanos en Erebor. | F9: 2018.0 | G9: 2018-12-10 | H9: https://doi.org/10.83190/yn8d9660 | I9: VALID_TARGET_REFERENCE | J9: MEDIUM | K9: VALID_CONTEXTUAL_REFERENCE | L9: Peter Jacksonの映画三部作が主対象だが、原作「The Hobbit」とTolkienを明示。映画化作品経由の参照 | M9: OABASEV1_060ac2b6934cc9ab | N9: W000013953 | O9: W7172534944
A10: 30 | B10: D.H. Lawrence | C10: D. H. Lawrence | D10: Westernness: A Meditation by Alan Williamson | E10: B o o k R e v i e w s Westernness: A Meditation. By Alan Williamson. Charlottesville: University of Virginia Press, 2006. 182 pages, $29.50. Reviewed by Diane Quantic Wichita State University Alan Williamson calls his study Westemness “a meditation,” “a fugue of accu­ mulating impressions” (7). Although the title seems sweeping, Williamson focuses primarily on afew authors and works from California and New Mexico. For example, in his first chapter, “Cather and Romance,” he considers only Death Comes for the Archbishop (1927), with brief mention of Song of the Lark (1915) and O Pioneers! (1913). In subsequent chapters, he treats “Yosemite Painters” Albert Bierstadt, Thomas Hill, and William Keith in just three-anda -half pages but with fine color reproductions of their works. D. H. Lawrence Photographer unknown. “Theodore Roosevelt and his dog Skip, on a bearhunt , West Divide Creek, near New Castle, Colorado, April 1905.” Neg. no. 335695. Courtesy of the American Museum ofNatural History Library. b o o k R e v ie w s and Yvor Winters are “Two Convalescents.” In four pages, he mentions Georgia O ’Keeffe in the context of Las Trampas and Chimayo. There are discussions of the Tonalism of the early-twentieth-century Monterrey painters and Robinson Jeffers. Steinbeck is considered in the context of the Tao. Raymond Chandler and the poets (unknown to this reader) James McMichael and Frank Bidart are covered in a chapter on Southern California. He places his discussion of Leslie Marmon Silko’sCeremony (1977) in a chapter titled “Highway 66” that focuses on negative aspects of European American culture. The California painter Wayne Thiebaud gets only four-and-a-half pages, but the poet Gary Snyder is central to two chapters, including one on the influence of Eastern culture on California poets. Finally, Williamson considers Montana and Young Men and Fire (1992) by Norman Maclean. To say the least, I find this an odd mix of “westemness” that means some­ thing quite different to me and, I would guess, to most students of western literature than it does to Williamson. The term “meditation,” like the recently controversial “memoir,” apparently gives an author more authority over his material than does a “systematic history,” for which Williams admits he “lackjs] the competence” (7). I would agree: it seems odd to read commentary on Cather’sromanticism and Death Comes for the Archbishop in the context of Richard Chase’sThe American Novel and Its Tradition (1957), citing the Vintage edition of the novel, with no reference to Susan Rosowski’sstudy of The Voyage Perilous (1986) or the scholarly edition of the text. Williamson’snotes vary in length and number from chapter to chapter, but in all of his discussions he relies on only a few sources outside his primary texts. He does not bring to his “meditation” the depth and range of scholarship one usually expects from a scholarly text. Nevertheless, I find his readings of the works by Cather, Steinbeck, and Maclean to be refreshing and insightful. Perhaps the key to appreciating a “meditation” is to recognize it as the author’s attempt to share a thoughtful consideration of certain texts in an effort to place those works within one’s own sense of “westemness.” Even though Williamson does not succeed in explaining his concept of the term adequately, he does add to my appreciation of several texts that embody my own sense of “westemness.” ... | F10: 2007.0 | G10: 2007-01-01 | H10: https://doi.org/10.1353/wal.2007.0027 | I10: VALID_TARGET_REFERENCE | J10: HIGH | K10: DIRECT_TARGET_REFERENCE | L10: 著者名ターゲット：評対象書にD. H. Lawrenceを扱う章あり | M10: OABASEV1_0b80a14c51a41611 | N10: W000030498 | O10: W2761953010
A11: 31 | B11: Ulysses | C11: James Joyce | D11: Homer, Turko, Little Harry: Cultural Memory and the Ethics of Premediation in James Joyce’s Ulysses | F11: 2019.0 | G11: 2019-06-06 | I11: VALID_TARGET_REFERENCE | J11: HIGH | K11: DIRECT_TARGET_REFERENCE | M11: OABASEV1_c1b54bf68ca97b4e | N11: W000030950 | O11: W7056874470
