Workbook

Sheet Instructions
A1: Open Library R2+A1 split-edition human audit v1
A3: Field | B3: Value
A4: Review packet freeze commit | B4: 32d95c3de27eabee635cb54e930f7c791a6822b3
A5: Frozen raw LLM routing commit | B5: 9d4a2d0ce50cc5335e06672732aa060d3a3be124
A6: Review cases | B6: 118
A7: Project works | B7: 17
A8: Fixed components | B8: 82
A9: LLM row-level answers shown? | B9: No — intentionally withheld
A11: How to review
A12: 1 | B12: Review only the bibliographic evidence shown in the Review sheet and the fixed component definitions in Components.
A13: 2 | B13: Fill the yellow columns: human_routing_decision, human_component_id, human_confidence, human_note.
A14: 3 | B14: ASSIGN_COMPONENT: choose exactly one component belonging to the same project_work_id.
A15: 4 | B15: HOLD_UNRESOLVED: leave human_component_id blank when the available evidence is insufficient.
A16: 5 | B16: REGISTRY_ISSUE: use when the fixed component ontology itself is inadequate; leave component blank and explain in human_note.
A17: 6 | B17: DETACH means detach from the erroneous predecessor grouping; it is not a corpus-scope exclusion.
A18: 7 | B18: EXCLUDE_APPARATUS applies only to components already defined as catalogue/study/apparatus by the frozen human plan.
A19: 8 | B19: Do not decompose an omnibus or anthology into constituent literary works. Route the edition as a publication-level unit.
A20: 9 | B20: This 118-row packet combines targeted review and a deterministic validation sample; do not treat it as a simple random sample of all 508 editions.
A22: Selection composition
A23: Selection stage | B23: New rows
A24: All LOW/MEDIUM frozen LLM confidence | B24: 57
A25: All DETACH / EXCLUDE_APPARATUS assignments | B25: 28
A26: HIGH primary-successor sample | B26: 3
A27: HIGH assignment sample | B27: 17
A28: HIGH HOLD sample | B28: 13
A29: Total | B29: 118

Sheet Review
A1: audit_case_id | B1: priority_rank | C1: project_work_id | D1: target_title | E1: target_author | F1: current_ol_work_id | G1: edition_key | H1: edition_title | I1: edition_subtitle | J1: publish_date | K1: publishers | L1: edition_author_keys | M1: pages | N1: human_resolution_confidence | O1: human_routing_decision | P1: human_component_id | Q1: human_confidence | R1: human_note | S1: selected_component_label | T1: selected_role_hint | U1: row_qc
A2: SERH0001 | B2: 1 | C2: W000014024 | D2: Henry James | E2: Henry James | F2: OL276471W | G2: OL19324269M | H2: Henry James | I2: representative selections | J2: 1966 | K2: University of Illinois Press | L2: /authors/OL21001A | N2: HIGH | O2: ASSIGN_COMPONENT | P2: W000014024_C08 | Q2: MEDIUM | R2: Subtitle 'representative selections' matches C08; 1966 University of Illinois Press issue is plausibly a reprint of the 1941 selection but equivalence is not shown. | S2: =IF(P2="","",IFERROR(VLOOKUP(P2,Components!$E$2:$H$83,3,FALSE()),"INVALID")) -> Representative selections | T2: =IF(P2="","",IFERROR(VLOOKUP(P2,Components!$E$2:$H$83,4,FALSE()),"INVALID")) -> SUCCESSOR | U2: =IF(O2="","",IF(O2="ASSIGN_COMPONENT",IF(P2<>"","OK","CHECK: component required"),IF(O2="HOLD_UNRESOLVED",IF(P2="","OK","CHECK: clear component"),IF(O2="REGISTRY_ISSUE",IF(R2<>"","OK","CHECK: note required"),"CHECK")))) -> OK
A3: SERH0002 | B3: 1 | C3: W000014024 | D3: Henry James | E3: Henry James | F3: OL276471W | G3: OL1090575M | H3: Henry James | I3: selected works. | J3: 1994 | K3: Gramercy Books || Distributed by Random House Value Pub. || Gramercy | L3: /authors/OL21001A | M3: 655 | N3: HIGH | O3: HOLD_UNRESOLVED | Q3: MEDIUM | R3: 'selected works.' (Gramercy 1994, 655 pp) has no contents listed. Likely a fiction omnibus (C05) but could be a mixed selection; no component for generic selected works. | S3: =IF(P3="","",IFERROR(VLOOKUP(P3,Components!$E$2:$H$83,3,FALSE()),"INVALID")) | T3: =IF(P3="","",IFERROR(VLOOKUP(P3,Components!$E$2:$H$83,4,FALSE()),"INVALID")) | U3: =IF(O3="","",IF(O3="ASSIGN_COMPONENT",IF(P3<>"","OK","CHECK: component required"),IF(O3="HOLD_UNRESOLVED",IF(P3="","OK","CHECK: clear component"),IF(O3="REGISTRY_ISSUE",IF(R3<>"","OK","CHECK: note required"),"CHECK")))) -> OK
A4: SERH0003 | B4: 1 | C4: W000014024 | D4: Henry James | E4: Henry James | F4: OL276471W | G4: OL7770273M | H4: Henry James | I4: Selected Fiction | J4: April 21, 1964 | K4: Dutton | L4: /authors/OL21001A | M4: 609 | N4: HIGH | O4: ASSIGN_COMPONENT | P4: W000014024_C05 | Q4: MEDIUM | R4: 'Selected Fiction' (Dutton 1964, 609 pp) fits the selected-fiction omnibus component by label; constituent works not listed. | S4: =IF(P4="","",IFERROR(VLOOKUP(P4,Components!$E$2:$H$83,3,FALSE()),"INVALID")) -> Selected-fiction / selected-novels omnibus | T4: =IF(P4="","",IFERROR(VLOOKUP(P4,Components!$E$2:$H$83,4,FALSE()),"INVALID")) -> SUCCESSOR | U4: =IF(O4="","",IF(O4="ASSIGN_COMPONENT",IF(P4<>"","OK","CHECK: component required"),IF(O4="HOLD_UNRESOLVED",IF(P4="","OK","CHECK: clear component"),IF(O4="REGISTRY_ISSUE",IF(R4<>"","OK","CHECK: note required"),"CHECK")))) -> OK
A5: SERH0004 | B5: 1 | C5: W000014024 | D5: Henry James | E5: Henry James | F5: OL276471W | G5: OL7692691M | H5: Henry James | I5: Selected Letters | J5: February 1, 1990 | K5: Belknap Press | L5: /authors/OL21001A | M5: 490 | N5: HIGH | O5: REGISTRY_ISSUE | Q5: MEDIUM | R5: 'Selected Letters' (Belknap 1990) is a letters selection distinct from both C02 (Benson/Monod) and C03 (A Life in Letters). Ontology lacks a general selected-letters component. | S5: =IF(P5="","",IFERROR(VLOOKUP(P5,Components!$E$2:$H$83,3,FALSE()),"INVALID")) | T5: =IF(P5="","",IFERROR(VLOOKUP(P5,Components!$E$2:$H$83,4,FALSE()),"INVALID")) | U5: =IF(O5="","",IF(O5="ASSIGN_COMPONENT",IF(P5<>"","OK","CHECK: component required"),IF(O5="HOLD_UNRESOLVED",IF(P5="","OK","CHECK: clear component"),IF(O5="REGISTRY_ISSUE",IF(R5<>"","OK","CHECK: note required"),"CHECK")))) -> OK
A6: SERH0005 | B6: 1 | C6: W000014024 | D6: Henry James | E6: Henry James | F6: OL276471W | G6: OL9800227M | H6: Henry James | J6: June 19, 2000 | K6: Penguin Books | L6: /authors/OL21001A | M6: 704 | N6: HIGH | O6: HOLD_UNRESOLVED | Q6: MEDIUM | R6: No subtitle. Penguin 2000, 704 pp; the frozen record lists 'A Life in Letters (Penguin Classics)' with a June 19, 2000 date, so C03 is likely, but this row itself shows no content evidence. | S6: =IF(P6="","",IFERROR(VLOOKUP(P6,Components!$E$2:$H$83,3,FALSE()),"INVALID")) | T6: =IF(P6="","",IFERROR(VLOOKUP(P6,Components!$E$2:$H$83,4,FALSE()),"INVALID")) | U6: =IF(O6="","",IF(O6="ASSIGN_COMPONENT",IF(P6<>"","OK","CHECK: component required"),IF(O6="HOLD_UNRESOLVED",IF(P6="","OK","CHECK: clear component"),IF(O6="REGISTRY_ISSUE",IF(R6<>"","OK","CHECK: note required"),"CHECK")))) -> OK
A7: SERH0006 | B7: 2 | C7: W000031472 | D7: Galen | E7: Galen | F7: OL988425W | G7: OL24290200M | H7: Galen | J7: 2003 | K7: Cambridge University Press | N7: HIGH | O7: HOLD_UNRESOLVED | Q7: MEDIUM | R7: No subtitle, no author key; CUP 2003 could be any of the three Cambridge treatise editions. | S7: =IF(P7="","",IFERROR(VLOOKUP(P7,Components!$E$2:$H$83,3,FALSE()),"INVALID")) | T7: =IF(P7="","",IFERROR(VLOOKUP(P7,Components!$E$2:$H$83,4,FALSE()),"INVALID")) | U7: =IF(O7="","",IF(O7="ASSIGN_COMPONENT",IF(P7<>"","OK","CHECK: component required"),IF(O7="HOLD_UNRESOLVED",IF(P7="","OK","CHECK: clear component"),IF(O7="REGISTRY_ISSUE",IF(R7<>"","OK","CHECK: note required"),"CHECK")))) -> OK
A8: SERH0007 | B8: 2 | C8: W000031472 | D8: Galen | E8: Galen | F8: OL988425W | G8: OL7748277M | H8: Galen | I8: On Antecedent Causes (Cambridge Classical Texts and Commentaries) | J8: June 10, 2004 | K8: Cambridge University Press | L8: /authors/OL91410A | M8: 365 | N8: HIGH | O8: ASSIGN_COMPONENT | P8: W000031472_C03 | Q8: HIGH | R8: Subtitle names On Antecedent Causes. | S8: =IF(P8="","",IFERROR(VLOOKUP(P8,Components!$E$2:$H$83,3,FALSE()),"INVALID")) -> On Antecedent Causes | T8: =IF(P8="","",IFERROR(VLOOKUP(P8,Components!$E$2:$H$83,4,FALSE()),"INVALID")) -> SUCCESSOR | U8: =IF(O8="","",IF(O8="ASSIGN_COMPONENT",IF(P8<>"","OK","CHECK: component required"),IF(O8="HOLD_UNRESOLVED",IF(P8="","OK","CHECK: clear component"),IF(O8="REGISTRY_ISSUE",IF(R8<>"","OK","CHECK: note required"),"CHECK")))) -> OK
A9: SERH0008 | B9: 3 | C9: W000030498 | D9: D.H. Lawrence | E9: D. H. Lawrence | F9: OL7965965W | G9: OL19834864M | H9: D.H. Lawrence. | J9: 1928 | K9: E. Benn | L9: /authors/OL19964A | M9: 31 | N9: HIGH | O9: ASSIGN_COMPONENT | P9: W000030498_C01 | Q9: MEDIUM | R9: No subtitle, but a 31-page E. Benn 1928 pamphlet corresponds to the 1928 'selected poems' line in the frozen record (same pattern as the Benn 1921 Emerson pamphlet). Short poetry selection; title-only evidence. | S9: =IF(P9="","",IFERROR(VLOOKUP(P9,Components!$E$2:$H$83,3,FALSE()),"INVALID")) -> Selected Poems | T9: =IF(P9="","",IFERROR(VLOOKUP(P9,Components!$E$2:$H$83,4,FALSE()),"INVALID")) -> SUCCESSOR | U9: =IF(O9="","",IF(O9="ASSIGN_COMPONENT",IF(P9<>"","OK","CHECK: component required"),IF(O9="HOLD_UNRESOLVED",IF(P9="","OK","CHECK: clear component"),IF(O9="REGISTRY_ISSUE",IF(R9<>"","OK","CHECK: note required"),"CHECK")))) -> OK
A10: SERH0009 | B10: 3 | C10: W000030498 | D10: D.H. Lawrence | E10: D. H. Lawrence | F10: OL7965965W | G10: OL20573625M | H10: D.H. Lawrence. | J10: 1928 | K10: E. Benn | L10: /authors/OL19964A | M10: 31 | N10: HIGH | O10: ASSIGN_COMPONENT | P10: W000030498_C01 | Q10: MEDIUM | R10: No subtitle, but a 31-page E. Benn 1928 pamphlet corresponds to the 1928 'selected poems' line in the frozen record (same pattern as the Benn 1921 Emerson pamphlet). Short poetry selection; title-only evidence. | S10: =IF(P10="","",IFERROR(VLOOKUP(P10,Components!$E$2:$H$83,3,FALSE()),"INVALID")) -> Selected Poems | T10: =IF(P10="","",IFERROR(VLOOKUP(P10,Components!$E$2:$H$83,4,FALSE()),"INVALID")) -> SUCCESSOR | U10: =IF(O10="","",IF(O10="ASSIGN_COMPONENT",IF(P10<>"","OK","CHECK: component required"),IF(O10="HOLD_UNRESOLVED",IF(P10="","OK","CHECK: clear component"),IF(O10="REGISTRY_ISSUE",IF(R10<>"","OK","CHECK: note required"),"CHECK")))) -> OK
A11: SERH0010 | B11: 3 | C11: W000030498 | D11: D.H. Lawrence | E11: D. H. Lawrence | F11: OL7965965W | G11: OL19844723M | H11: D.H. Lawrence | I11: poems | J11: 1968 | K11: Macmillan | L11: /authors/OL19964A | M11: 120 | N11: HIGH | O11: ASSIGN_COMPONENT | P11: W000030498_C01 | Q11: HIGH | R11: Subtitle 'poems' (Macmillan 1968, 120 pp): a selected-poetry edition. | S11: =IF(P11="","",IFERROR(VLOOKUP(P11,Components!$E$2:$H$83,3,FALSE()),"INVALID")) -> Selected Poems | T11: =IF(P11="","",IFERROR(VLOOKUP(P11,Components!$E$2:$H$83,4,FALSE()),"INVALID")) -> SUCCESSOR | U11: =IF(O11="","",IF(O11="ASSIGN_COMPONENT",IF(P11<>"","OK","CHECK: component required"),IF(O11="HOLD_UNRESOLVED",IF(P11="","OK","CHECK: clear component"),IF(O11="REGISTRY_ISSUE",IF(R11<>"","OK","CHECK: note required"),"CHECK")))) -> OK
A12: SERH0011 | B12: 3 | C12: W000030498 | D12: D.H. Lawrence | E12: D. H. Lawrence | F12: OL7965965W | G12: OL4717145M | H12: D. H. Lawrence | I12: [poems]. | J12: 1977 | K12: Norwood Editions | L12: /authors/OL19964A | M12: 30 | N12: HIGH | O12: ASSIGN_COMPONENT | P12: W000030498_C01 | Q12: HIGH | R12: Subtitle '[poems]' (Norwood 1977, 30 pp): reprint-size poetry selection. | S12: =IF(P12="","",IFERROR(VLOOKUP(P12,Components!$E$2:$H$83,3,FALSE()),"INVALID")) -> Selected Poems | T12: =IF(P12="","",IFERROR(VLOOKUP(P12,Components!$E$2:$H$83,4,FALSE()),"INVALID")) -> SUCCESSOR | U12: =IF(O12="","",IF(O12="ASSIGN_COMPONENT",IF(P12<>"","OK","CHECK: component required"),IF(O12="HOLD_UNRESOLVED",IF(P12="","OK","CHECK: clear component"),IF(O12="REGISTRY_ISSUE",IF(R12<>"","OK","CHECK: note required"),"CHECK")))) -> OK
A13: SERH0012 | B13: 3 | C13: W000030498 | D13: D.H. Lawrence | E13: D. H. Lawrence | F13: OL7965965W | G13: OL1856256M | H13: D.H. Lawrence | I13: selected poetry and non-fictional prose | J13: 1991 | K13: Routledge | L13: /authors/OL19964A | M13: 258 | N13: HIGH | O13: REGISTRY_ISSUE | Q13: MEDIUM | R13: 'selected poetry and non-fictional prose' (Routledge 1991) mixes C01 (poetry) and C04 (criticism/prose); no mixed-selection component exists for Lawrence. | S13: =IF(P13="","",IFERROR(VLOOKUP(P13,Components!$E$2:$H$83,3,FALSE()),"INVALID")) | T13: =IF(P13="","",IFERROR(VLOOKUP(P13,Components!$E$2:$H$83,4,FALSE()),"INVALID")) | U13: =IF(O13="","",IF(O13="ASSIGN_COMPONENT",IF(P13<>"","OK","CHECK: component required"),IF(O13="HOLD_UNRESOLVED",IF(P13="","OK","CHECK: clear component"),IF(O13="REGISTRY_ISSUE",IF(R13<>"","OK","CHECK: note required"),"CHECK")))) -> OK
A14: SERH0013 | B14: 3 | C14: W000030498 | D14: D.H. Lawrence | E14: D. H. Lawrence | F14: OL7965965W | G14: OL15542824M | H14: D.H. Lawrence | I14: an exceptional collection of first editions, autograph material, manuscripts, original paintings, photographs, and association items | J14: 2002 | K14: Simon Finch Rare Books Limited | L14: /authors/OL19964A | M14: 175 | N14: HIGH | O14: ASSIGN_COMPONENT | P14: W000030498_C06 | Q14: HIGH | R14: Simon Finch Rare Books 2002 dealer's catalogue of first editions, manuscripts, paintings, etc.: analogous to the C06 catalogue component (EXCLUDE_APPARATUS). | S14: =IF(P14="","",IFERROR(VLOOKUP(P14,Components!$E$2:$H$83,3,FALSE()),"INVALID")) -> Rare-book catalogue | T14: =IF(P14="","",IFERROR(VLOOKUP(P14,Components!$E$2:$H$83,4,FALSE()),"INVALID")) -> EXCLUDE_APPARATUS | U14: =IF(O14="","",IF(O14="ASSIGN_COMPONENT",IF(P14<>"","OK","CHECK: component required"),IF(O14="HOLD_UNRESOLVED",IF(P14="","OK","CHECK: clear component"),IF(O14="REGISTRY_ISSUE",IF(R14<>"","OK","CHECK: note required"),"CHECK")))) -> OK
A15: SERH0014 | B15: 3 | C15: W000030498 | D15: D.H. Lawrence | E15: D. H. Lawrence | F15: OL7965965W | G15: OL9208520M | H15: D H Lawrence | I15: Sons and Lovers, the Fox, Love Among the Haystacks, Aaron's Rod, the Ladybird, Women in Love | J15: December 1989 | K15: Book Sales | L15: /authors/OL19964A | N15: HIGH | O15: ASSIGN_COMPONENT | P15: W000030498_C02 | Q15: HIGH | R15: Subtitle lists the six-work omnibus named in C02; route as one unit. | S15: =IF(P15="","",IFERROR(VLOOKUP(P15,Components!$E$2:$H$83,3,FALSE()),"INVALID")) -> Novel omnibus | T15: =IF(P15="","",IFERROR(VLOOKUP(P15,Components!$E$2:$H$83,4,FALSE()),"INVALID")) -> SUCCESSOR | U15: =IF(O15="","",IF(O15="ASSIGN_COMPONENT",IF(P15<>"","OK","CHECK: component required"),IF(O15="HOLD_UNRESOLVED",IF(P15="","OK","CHECK: clear component"),IF(O15="REGISTRY_ISSUE",IF(R15<>"","OK","CHECK: note required"),"CHECK")))) -> OK
A16: SERH0015 | B16: 4 | C16: W000023649 | D16: Ralph Waldo Emerson | E16: Ralph Waldo Emerson | F16: OL62231W | G16: OL15582404M | H16: Ralph Waldo Emerson | I16: passages from his writings | K16: Unity Office | L16: /authors/OL18405A | M16: 30 | N16: MEDIUM | O16: ASSIGN_COMPONENT | P16: W000023649_C01 | Q16: MEDIUM | R16: Subtitle 'passages from his writings' (Unity Office, 30 pp, undated) matches C01's wording, though the life sketch / reading guide is not mentioned. | S16: =IF(P16="","",IFERROR(VLOOKUP(P16,Components!$E$2:$H$83,3,FALSE()),"INVALID")) -> Passages from his writings | T16: =IF(P16="","",IFERROR(VLOOKUP(P16,Components!$E$2:$H$83,4,FALSE()),"INVALID")) -> SUCCESSOR | U16: =IF(O16="","",IF(O16="ASSIGN_COMPONENT",IF(P16<>"","OK","CHECK: component required"),IF(O16="HOLD_UNRESOLVED",IF(P16="","OK","CHECK: clear component"),IF(O16="REGISTRY_ISSUE",IF(R16<>"","OK","CHECK: note required"),"CHECK")))) -> OK
A17: SERH0016 | B17: 4 | C17: W000023649 | D17: Ralph Waldo Emerson | E17: Ralph Waldo Emerson | F17: OL62231W | G17: OL7106368M | H17: Ralph Waldo Emerson. | J17: 1921 | K17: Benn | L17: /authors/OL18405A | M17: 31 | N17: MEDIUM | O17: HOLD_UNRESOLVED | Q17: MEDIUM | R17: No subtitle; Benn 1921, 31 pp. A short pamphlet selection (likely poems) that fits none of the Emerson components clearly (C05 mixed prose/poetry is the nearest). | S17: =IF(P17="","",IFERROR(VLOOKUP(P17,Components!$E$2:$H$83,3,FALSE()),"INVALID")) | T17: =IF(P17="","",IFERROR(VLOOKUP(P17,Components!$E$2:$H$83,4,FALSE()),"INVALID")) | U17: =IF(O17="","",IF(O17="ASSIGN_COMPONENT",IF(P17<>"","OK","CHECK: component required"),IF(O17="HOLD_UNRESOLVED",IF(P17="","OK","CHECK: clear component"),IF(O17="REGISTRY_ISSUE",IF(R17<>"","OK","CHECK: note required"),"CHECK")))) -> OK
A18: SERH0017 | B18: 4 | C18: W000023649 | D18: Ralph Waldo Emerson | E18: Ralph Waldo Emerson | F18: OL62231W | G18: OL23265825M | H18: Ralph Waldo Emerson | I18: essays and journals. | J18: 1968 | K18: Doubleday | L18: /authors/OL18405A | M18: 671 | N18: MEDIUM | O18: ASSIGN_COMPONENT | P18: W000023649_C04 | Q18: HIGH | R18: Subtitle 'essays and journals.' (Doubleday 1968). | S18: =IF(P18="","",IFERROR(VLOOKUP(P18,Components!$E$2:$H$83,3,FALSE()),"INVALID")) -> Essays and journals | T18: =IF(P18="","",IFERROR(VLOOKUP(P18,Components!$E$2:$H$83,4,FALSE()),"INVALID")) -> SUCCESSOR | U18: =IF(O18="","",IF(O18="ASSIGN_COMPONENT",IF(P18<>"","OK","CHECK: component required"),IF(O18="HOLD_UNRESOLVED",IF(P18="","OK","CHECK: clear component"),IF(O18="REGISTRY_ISSUE",IF(R18<>"","OK","CHECK: note required"),"CHECK")))) -> OK
A19: SERH0018 | B19: 5 | C19: W000003023 | D19: Arnold | E19: Matthew Arnold | F19: OL1336767W | G19: OL19362026M | H19: Arnold | I19: poetry and prose | J19: 1946 | K19: (s.n.) | L19: /authors/OL136194A | N19: MEDIUM | O19: ASSIGN_COMPONENT | P19: W000003023_C01 | Q19: HIGH | R19: 'poetry and prose', 1946: the 1939/1946 selection defined as C01. | S19: =IF(P19="","",IFERROR(VLOOKUP(P19,Components!$E$2:$H$83,3,FALSE()),"INVALID")) -> Poetry and prose | T19: =IF(P19="","",IFERROR(VLOOKUP(P19,Components!$E$2:$H$83,4,FALSE()),"INVALID")) -> SUCCESSOR | U19: =IF(O19="","",IF(O19="ASSIGN_COMPONENT",IF(P19<>"","OK","CHECK: component required"),IF(O19="HOLD_UNRESOLVED",IF(P19="","OK","CHECK: clear component"),IF(O19="REGISTRY_ISSUE",IF(R19<>"","OK","CHECK: note required"),"CHECK")))) -> OK
A20: SERH0019 | B20: 5 | C20: W000003023 | D20: Arnold | E20: Matthew Arnold | F20: OL1336767W | G20: OL22304281M | H20: Arnold | I20: poems | J20: 1985 | K20: Penguin | L20: /authors/OL136194A | M20: 267 | N20: MEDIUM | O20: REGISTRY_ISSUE | Q20: MEDIUM | R20: 'poems' (Penguin 1985, 267 pp) is a poetry selection outside the Everyman's lineage that C02 is restricted to. Suggest widening C02 to 'Poems selections' or adding a Penguin poems component. | S20: =IF(P20="","",IFERROR(VLOOKUP(P20,Components!$E$2:$H$83,3,FALSE()),"INVALID")) | T20: =IF(P20="","",IFERROR(VLOOKUP(P20,Components!$E$2:$H$83,4,FALSE()),"INVALID")) | U20: =IF(O20="","",IF(O20="ASSIGN_COMPONENT",IF(P20<>"","OK","CHECK: component required"),IF(O20="HOLD_UNRESOLVED",IF(P20="","OK","CHECK: clear component"),IF(O20="REGISTRY_ISSUE",IF(R20<>"","OK","CHECK: note required"),"CHECK")))) -> OK
A21: SERH0020 | B21: 6 | C21: W000005351 | D21: Chaucer | E21: Geoffrey Chaucer | F21: OL15378100W | G21: OL13663209M | H21: Chaucer | J21: 1963 | K21: Dell | L21: /authors/OL37436A | N21: HIGH | O21: HOLD_UNRESOLVED | Q21: MEDIUM | R21: No subtitle; Dell 1963 paperback. Contents (Canterbury Tales selection vs other) not shown. | S21: =IF(P21="","",IFERROR(VLOOKUP(P21,Components!$E$2:$H$83,3,FALSE()),"INVALID")) | T21: =IF(P21="","",IFERROR(VLOOKUP(P21,Components!$E$2:$H$83,4,FALSE()),"INVALID")) | U21: =IF(O21="","",IF(O21="ASSIGN_COMPONENT",IF(P21<>"","OK","CHECK: component required"),IF(O21="HOLD_UNRESOLVED",IF(P21="","OK","CHECK: clear component"),IF(O21="REGISTRY_ISSUE",IF(R21<>"","OK","CHECK: note required"),"CHECK")))) -> OK
A22: SERH0021 | B22: 6 | C22: W000005351 | D22: Chaucer | E22: Geoffrey Chaucer | F22: OL15378100W | G22: OL5890008M | H22: Chaucer. | J22: 1963 | K22: Dell Pub. Co. | L22: /authors/OL37436A | M22: 352 | N22: HIGH | O22: HOLD_UNRESOLVED | Q22: MEDIUM | R22: No subtitle; Dell 1963 paperback. Contents (Canterbury Tales selection vs other) not shown. | S22: =IF(P22="","",IFERROR(VLOOKUP(P22,Components!$E$2:$H$83,3,FALSE()),"INVALID")) | T22: =IF(P22="","",IFERROR(VLOOKUP(P22,Components!$E$2:$H$83,4,FALSE()),"INVALID")) | U22: =IF(O22="","",IF(O22="ASSIGN_COMPONENT",IF(P22<>"","OK","CHECK: component required"),IF(O22="HOLD_UNRESOLVED",IF(P22="","OK","CHECK: clear component"),IF(O22="REGISTRY_ISSUE",IF(R22<>"","OK","CHECK: note required"),"CHECK")))) -> OK
A23: SERH0022 | B23: 6 | C23: W000005351 | D23: Chaucer | E23: Geoffrey Chaucer | F23: OL15378100W | G23: OL21162256M | H23: Chaucer | I23: sources and backgrounds | J23: 1977 | K23: Oxford UniversityPress | L23: /authors/OL37436A | M23: 507 | N23: HIGH | O23: ASSIGN_COMPONENT | P23: W000005351_C04 | Q23: HIGH | R23: 'sources and backgrounds': study apparatus. | S23: =IF(P23="","",IFERROR(VLOOKUP(P23,Components!$E$2:$H$83,3,FALSE()),"INVALID")) -> Study apparatus / CD-ROM manual | T23: =IF(P23="","",IFERROR(VLOOKUP(P23,Components!$E$2:$H$83,4,FALSE()),"INVALID")) -> EXCLUDE_APPARATUS | U23: =IF(O23="","",IF(O23="ASSIGN_COMPONENT",IF(P23<>"","OK","CHECK: component required"),IF(O23="HOLD_UNRESOLVED",IF(P23="","OK","CHECK: clear component"),IF(O23="REGISTRY_ISSUE",IF(R23<>"","OK","CHECK: note required"),"CHECK")))) -> OK
A24: SERH0023 | B24: 6 | C24: W000005351 | D24: Chaucer | E24: Geoffrey Chaucer | F24: OL15378100W | G24: OL11928746M | H24: Chaucer | I24: The Prioresses Tale, Sir Thopas, The Monkes Tale, The Clerkes Tale, The Squieres Tale From The Canterbury Tales | J24: January 17, 2007 | K24: Kessinger Publishing, LLC | L24: /authors/OL37436A | M24: 540 | N24: HIGH | O24: ASSIGN_COMPONENT | P24: W000005351_C01 | Q24: HIGH | R24: Subtitle lists Prioress / Sir Thopas / Monk / Clerk / Squire tales from the Canterbury Tales. | S24: =IF(P24="","",IFERROR(VLOOKUP(P24,Components!$E$2:$H$83,3,FALSE()),"INVALID")) -> Canterbury Tales selections | T24: =IF(P24="","",IFERROR(VLOOKUP(P24,Components!$E$2:$H$83,4,FALSE()),"INVALID")) -> SUCCESSOR | U24: =IF(O24="","",IF(O24="ASSIGN_COMPONENT",IF(P24<>"","OK","CHECK: component required"),IF(O24="HOLD_UNRESOLVED",IF(P24="","OK","CHECK: clear component"),IF(O24="REGISTRY_ISSUE",IF(R24<>"","OK","CHECK: note required"),"CHECK")))) -> OK
A25: SERH0024 | B25: 6 | C25: W000005351 | D25: Chaucer | E25: Geoffrey Chaucer | F25: OL15378100W | G25: OL11067624M | H25: Chaucer | J25: January 24, 1948 | K25: Viking Adult | L25: /authors/OL37436A | N25: HIGH | O25: HOLD_UNRESOLVED | Q25: MEDIUM | R25: No subtitle; Viking 1948. Could be a broad portable selection; contents not shown. | S25: =IF(P25="","",IFERROR(VLOOKUP(P25,Components!$E$2:$H$83,3,FALSE()),"INVALID")) | T25: =IF(P25="","",IFERROR(VLOOKUP(P25,Components!$E$2:$H$83,4,FALSE()),"INVALID")) | U25: =IF(O25="","",IF(O25="ASSIGN_COMPONENT",IF(P25<>"","OK","CHECK: component required"),IF(O25="HOLD_UNRESOLVED",IF(P25="","OK","CHECK: clear component"),IF(O25="REGISTRY_ISSUE",IF(R25<>"","OK","CHECK: note required"),"CHECK")))) -> OK
A26: SERH0025 | B26: 6 | C26: W000005351 | D26: Chaucer | E26: Geoffrey Chaucer | F26: OL15378100W | G26: OL7741850M | H26: Chaucer | I26: The Wife of Bath's Prologue on CD-ROM (The Canterbury Tales on CD-ROM) | J26: June 13, 1996 | K26: Cambridge University Press | L26: /authors/OL37436A | M26: 80 | N26: HIGH | O26: ASSIGN_COMPONENT | P26: W000005351_C04 | Q26: MEDIUM | R26: 'The Wife of Bath's Prologue on CD-ROM': electronic scholarly edition packaged with its 80-page manual (SERH0026). Routed with the CD-ROM apparatus component; could alternatively be read as a C01 text selection. | S26: =IF(P26="","",IFERROR(VLOOKUP(P26,Components!$E$2:$H$83,3,FALSE()),"INVALID")) -> Study apparatus / CD-ROM manual | T26: =IF(P26="","",IFERROR(VLOOKUP(P26,Components!$E$2:$H$83,4,FALSE()),"INVALID")) -> EXCLUDE_APPARATUS | U26: =IF(O26="","",IF(O26="ASSIGN_COMPONENT",IF(P26<>"","OK","CHECK: component required"),IF(O26="HOLD_UNRESOLVED",IF(P26="","OK","CHECK: clear component"),IF(O26="REGISTRY_ISSUE",IF(R26<>"","OK","CHECK: note required"),"CHECK")))) -> OK
A27: SERH0026 | B27: 6 | C27: W000005351 | D27: Chaucer | E27: Geoffrey Chaucer | F27: OL15378100W | G27: OL7746561M | H27: Chaucer | I27: The Wife of Bath's Prologue CD-ROM Manual (The Canterbury Tales on CD-ROM) | J27: June 27, 1996 | K27: Cambridge University Press | L27: /authors/OL37436A | M27: 80 | N27: HIGH | O27: ASSIGN_COMPONENT | P27: W000005351_C04 | Q27: HIGH | R27: CD-ROM manual: apparatus by definition. | S27: =IF(P27="","",IFERROR(VLOOKUP(P27,Components!$E$2:$H$83,3,FALSE()),"INVALID")) -> Study apparatus / CD-ROM manual | T27: =IF(P27="","",IFERROR(VLOOKUP(P27,Components!$E$2:$H$83,4,FALSE()),"INVALID")) -> EXCLUDE_APPARATUS | U27: =IF(O27="","",IF(O27="ASSIGN_COMPONENT",IF(P27<>"","OK","CHECK: component required"),IF(O27="HOLD_UNRESOLVED",IF(P27="","OK","CHECK: clear component"),IF(O27="REGISTRY_ISSUE",IF(R27<>"","OK","CHECK: note required"),"CHECK")))) -> OK
A28: SERH0027 | B28: 7 | C28: W000013400 | D28: Hans Christian Andersen | E28: Hans Christian Andersen | F28: OL25506W | G28: OL13069955M | H28: Hans Christian Andersen | J28: January 1, 1996 | K28: Panamericana Editorial | L28: /authors/OL25931A | M28: 176 | N28: HIGH | O28: HOLD_UNRESOLVED | Q28: MEDIUM | R28: No subtitle; Panamericana Editorial 1996, 176 pp (Spanish-language publisher). Probably a tale selection but not evidenced. | S28: =IF(P28="","",IFERROR(VLOOKUP(P28,Components!$E$2:$H$83,3,FALSE()),"INVALID")) | T28: =IF(P28="","",IFERROR(VLOOKUP(P28,Components!$E$2:$H$83,4,FALSE()),"INVALID")) | U28: =IF(O28="","",IF(O28="ASSIGN_COMPONENT",IF(P28<>"","OK","CHECK: component required"),IF(O28="HOLD_UNRESOLVED",IF(P28="","OK","CHECK: clear component"),IF(O28="REGISTRY_ISSUE",IF(R28<>"","OK","CHECK: note required"),"CHECK")))) -> OK
A29: SERH0028 | B29: 7 | C29: W000013400 | D29: Hans Christian Andersen | E29: Hans Christian Andersen | F29: OL25506W | G29: OL7507523M | H29: Hans Christian Andersen | I29: Stories and Fairy Tales | J29: October 14, 1993 | K29: Mammoth | L29: /authors/OL25931A || /authors/OL988759A | M29: 96 | N29: HIGH | O29: ASSIGN_COMPONENT | P29: W000013400_C01 | Q29: HIGH | R29: 'Stories and Fairy Tales'. | S29: =IF(P29="","",IFERROR(VLOOKUP(P29,Components!$E$2:$H$83,3,FALSE()),"INVALID")) -> Fairy-tale / story collections | T29: =IF(P29="","",IFERROR(VLOOKUP(P29,Components!$E$2:$H$83,4,FALSE()),"INVALID")) -> SUCCESSOR | U29: =IF(O29="","",IF(O29="ASSIGN_COMPONENT",IF(P29<>"","OK","CHECK: component required"),IF(O29="HOLD_UNRESOLVED",IF(P29="","OK","CHECK: clear component"),IF(O29="REGISTRY_ISSUE",IF(R29<>"","OK","CHECK: note required"),"CHECK")))) -> OK
A30: SERH0029 | B30: 8 | C30: W000014515 | D30: Louisa May Alcott | E30: Louisa May Alcott | F30: OL29984W | G30: OL23255939M | H30: Louisa May Alcott | J30: 1980 | K30: Chelsea House | L30: /authors/OL26680A | M30: 404 | N30: HIGH | O30: HOLD_UNRESOLVED | Q30: MEDIUM | R30: No subtitle; Chelsea House 1980, 404 pp. Could be the Chelsea House biographical series (C05) or a Chelsea House reissue of Cheney's Life, Letters, and Journals (C01, similar length). The registry may be treating a Cheney reissue as a separate biography; verify before routing. | S30: =IF(P30="","",IFERROR(VLOOKUP(P30,Components!$E$2:$H$83,3,FALSE()),"INVALID")) | T30: =IF(P30="","",IFERROR(VLOOKUP(P30,Components!$E$2:$H$83,4,FALSE()),"INVALID")) | U30: =IF(O30="","",IF(O30="ASSIGN_COMPONENT",IF(P30<>"","OK","CHECK: component required"),IF(O30="HOLD_UNRESOLVED",IF(P30="","OK","CHECK: clear component"),IF(O30="REGISTRY_ISSUE",IF(R30<>"","OK","CHECK: note required"),"CHECK")))) -> OK
A31: SERH0030 | B31: 8 | C31: W000014515 | D31: Louisa May Alcott | E31: Louisa May Alcott | F31: OL29984W | G31: OL4104648M | H31: Louisa May Alcott | J31: 1980 | K31: Chelsea House | L31: /authors/OL26680A | M31: 404 | N31: HIGH | O31: HOLD_UNRESOLVED | Q31: MEDIUM | R31: No subtitle; Chelsea House 1980, 404 pp. Could be the Chelsea House biographical series (C05) or a Chelsea House reissue of Cheney's Life, Letters, and Journals (C01, similar length). The registry may be treating a Cheney reissue as a separate biography; verify before routing. | S31: =IF(P31="","",IFERROR(VLOOKUP(P31,Components!$E$2:$H$83,3,FALSE()),"INVALID")) | T31: =IF(P31="","",IFERROR(VLOOKUP(P31,Components!$E$2:$H$83,4,FALSE()),"INVALID")) | U31: =IF(O31="","",IF(O31="ASSIGN_COMPONENT",IF(P31<>"","OK","CHECK: component required"),IF(O31="HOLD_UNRESOLVED",IF(P31="","OK","CHECK: clear component"),IF(O31="REGISTRY_ISSUE",IF(R31<>"","OK","CHECK: note required"),"CHECK")))) -> OK
A32: SERH0031 | B32: 8 | C32: W000014515 | D32: Louisa May Alcott | E32: Louisa May Alcott | F32: OL29984W | G32: OL1874676M | H32: Louisa May Alcott | I32: selected fiction | J32: 1990 | K32: Little, Brown | L32: /authors/OL26680A | M32: 478 | N32: HIGH | O32: ASSIGN_COMPONENT | P32: W000014515_C03 | Q32: HIGH | R32: 'selected fiction' / 'Selected Fiction'. | S32: =IF(P32="","",IFERROR(VLOOKUP(P32,Components!$E$2:$H$83,3,FALSE()),"INVALID")) -> Works / Selected Fiction | T32: =IF(P32="","",IFERROR(VLOOKUP(P32,Components!$E$2:$H$83,4,FALSE()),"INVALID")) -> DETACH | U32: =IF(O32="","",IF(O32="ASSIGN_COMPONENT",IF(P32<>"","OK","CHECK: component required"),IF(O32="HOLD_UNRESOLVED",IF(P32="","OK","CHECK: clear component"),IF(O32="REGISTRY_ISSUE",IF(R32<>"","OK","CHECK: note required"),"CHECK")))) -> OK
A33: SERH0032 | B33: 8 | C33: W000014515 | D33: Louisa May Alcott | E33: Louisa May Alcott | F33: OL29984W | G33: OL670532M | H33: Louisa May Alcott | I33: an intimate anthology | J33: 1997 | K33: Doubleday | L33: /authors/OL26680A | M33: 369 | N33: HIGH | O33: ASSIGN_COMPONENT | P33: W000014515_C04 | Q33: HIGH | R33: 'an intimate anthology'. | S33: =IF(P33="","",IFERROR(VLOOKUP(P33,Components!$E$2:$H$83,3,FALSE()),"INVALID")) -> An intimate anthology | T33: =IF(P33="","",IFERROR(VLOOKUP(P33,Components!$E$2:$H$83,4,FALSE()),"INVALID")) -> DETACH | U33: =IF(O33="","",IF(O33="ASSIGN_COMPONENT",IF(P33<>"","OK","CHECK: component required"),IF(O33="HOLD_UNRESOLVED",IF(P33="","OK","CHECK: clear component"),IF(O33="REGISTRY_ISSUE",IF(R33<>"","OK","CHECK: note required"),"CHECK")))) -> OK
A34: SERH0033 | B34: 8 | C34: W000014515 | D34: Louisa May Alcott | E34: Louisa May Alcott | F34: OL29984W | G34: OL6791295M | H34: Louisa May Alcott | I34: selected fiction | J34: 2001 | K34: University of Georgia Press | L34: /authors/OL26680A | M34: 478 | N34: HIGH | O34: ASSIGN_COMPONENT | P34: W000014515_C03 | Q34: HIGH | R34: 'selected fiction' / 'Selected Fiction'. | S34: =IF(P34="","",IFERROR(VLOOKUP(P34,Components!$E$2:$H$83,3,FALSE()),"INVALID")) -> Works / Selected Fiction | T34: =IF(P34="","",IFERROR(VLOOKUP(P34,Components!$E$2:$H$83,4,FALSE()),"INVALID")) -> DETACH | U34: =IF(O34="","",IF(O34="ASSIGN_COMPONENT",IF(P34<>"","OK","CHECK: component required"),IF(O34="HOLD_UNRESOLVED",IF(P34="","OK","CHECK: clear component"),IF(O34="REGISTRY_ISSUE",IF(R34<>"","OK","CHECK: note required"),"CHECK")))) -> OK
A35: SERH0034 | B35: 8 | C35: W000014515 | D35: Louisa May Alcott | E35: Louisa May Alcott | F35: OL29984W | G35: OL23274548M | H35: Little women ; little men ; Jo's boys | J35: 2005 | K35: Library of America || Distributed to the trade in the U.S. by Penguin Putnam | L35: /authors/OL26680A | M35: 1092 | N35: HIGH | O35: ASSIGN_COMPONENT | P35: W000014515_C02 | Q35: HIGH | R35: Title is the Little Women / Little Men / Jo's Boys omnibus (Library of America). | S35: =IF(P35="","",IFERROR(VLOOKUP(P35,Components!$E$2:$H$83,3,FALSE()),"INVALID")) -> Little Women / Little Men / Jo's Boys omnibus | T35: =IF(P35="","",IFERROR(VLOOKUP(P35,Components!$E$2:$H$83,4,FALSE()),"INVALID")) -> DETACH | U35: =IF(O35="","",IF(O35="ASSIGN_COMPONENT",IF(P35<>"","OK","CHECK: component required"),IF(O35="HOLD_UNRESOLVED",IF(P35="","OK","CHECK: clear component"),IF(O35="REGISTRY_ISSUE",IF(R35<>"","OK","CHECK: note required"),"CHECK")))) -> OK
A36: SERH0035 | B36: 8 | C36: W000014515 | D36: Louisa May Alcott | E36: Louisa May Alcott | F36: OL29984W | G36: OL9519170M | H36: Louisa May Alcott Her Life, Letters, and Journals | J36: April 2003 | K36: Fredonia Books (NL) | L36: /authors/OL26680A | M36: 416 | N36: HIGH | O36: ASSIGN_COMPONENT | P36: W000014515_C01 | Q36: HIGH | R36: Title/subtitle 'Her Life, Letters, and Journals'. | S36: =IF(P36="","",IFERROR(VLOOKUP(P36,Components!$E$2:$H$83,3,FALSE()),"INVALID")) -> Her Life, Letters, and Journals | T36: =IF(P36="","",IFERROR(VLOOKUP(P36,Components!$E$2:$H$83,4,FALSE()),"INVALID")) -> PRIMARY_SUCCESSOR_HINT | U36: =IF(O36="","",IF(O36="ASSIGN_COMPONENT",IF(P36<>"","OK","CHECK: component required"),IF(O36="HOLD_UNRESOLVED",IF(P36="","OK","CHECK: clear component"),IF(O36="REGISTRY_ISSUE",IF(R36<>"","OK","CHECK: note required"),"CHECK")))) -> OK
A37: SERH0036 | B37: 8 | C37: W000014515 | D37: Louisa May Alcott | E37: Louisa May Alcott | F37: OL29984W | G37: OL9896241M | H37: Louisa May Alcott | I37: Selected Fiction | J37: February 1991 | K37: Little Brown & Co (T) | L37: /authors/OL26680A || /authors/OL20936A || /authors/OL2866635A | M37: 320 | N37: HIGH | O37: ASSIGN_COMPONENT | P37: W000014515_C03 | Q37: HIGH | R37: 'selected fiction' / 'Selected Fiction'. | S37: =IF(P37="","",IFERROR(VLOOKUP(P37,Components!$E$2:$H$83,3,FALSE()),"INVALID")) -> Works / Selected Fiction | T37: =IF(P37="","",IFERROR(VLOOKUP(P37,Components!$E$2:$H$83,4,FALSE()),"INVALID")) -> DETACH | U37: =IF(O37="","",IF(O37="ASSIGN_COMPONENT",IF(P37<>"","OK","CHECK: component required"),IF(O37="HOLD_UNRESOLVED",IF(P37="","OK","CHECK: clear component"),IF(O37="REGISTRY_ISSUE",IF(R37<>"","OK","CHECK: note required"),"CHECK")))) -> OK
A38: SERH0037 | B38: 8 | C38: W000014515 | D38: Louisa May Alcott | E38: Louisa May Alcott | F38: OL29984W | G38: OL8192995M | H38: Works of Louisa May Alcott | J38: June 1986 | K38: Amereon Ltd | L38: /authors/OL26680A | N38: HIGH | O38: ASSIGN_COMPONENT | P38: W000014515_C03 | Q38: HIGH | R38: 'Works of Louisa May Alcott'. | S38: =IF(P38="","",IFERROR(VLOOKUP(P38,Components!$E$2:$H$83,3,FALSE()),"INVALID")) -> Works / Selected Fiction | T38: =IF(P38="","",IFERROR(VLOOKUP(P38,Components!$E$2:$H$83,4,FALSE()),"INVALID")) -> DETACH | U38: =IF(O38="","",IF(O38="ASSIGN_COMPONENT",IF(P38<>"","OK","CHECK: component required"),IF(O38="HOLD_UNRESOLVED",IF(P38="","OK","CHECK: clear component"),IF(O38="REGISTRY_ISSUE",IF(R38<>"","OK","CHECK: note required"),"CHECK")))) -> OK
A39: SERH0038 | B39: 8 | C39: W000014515 | D39: Louisa May Alcott | E39: Louisa May Alcott | F39: OL29984W | G39: OL9536147M | H39: Louisa May Alcott (American Men & Women of Letters) | J39: May 2004 | K39: Chelsea House Publications | N39: HIGH | O39: ASSIGN_COMPONENT | P39: W000014515_C05 | Q39: HIGH | R39: Title carries the 'American Men & Women of Letters' series; assigned per the C05 definition. Note that this series volume may itself be a reissue of Cheney (C01). | S39: =IF(P39="","",IFERROR(VLOOKUP(P39,Components!$E$2:$H$83,3,FALSE()),"INVALID")) -> American Men & Women of Letters biography | T39: =IF(P39="","",IFERROR(VLOOKUP(P39,Components!$E$2:$H$83,4,FALSE()),"INVALID")) -> DETACH | U39: =IF(O39="","",IF(O39="ASSIGN_COMPONENT",IF(P39<>"","OK","CHECK: component required"),IF(O39="HOLD_UNRESOLVED",IF(P39="","OK","CHECK: clear component"),IF(O39="REGISTRY_ISSUE",IF(R39<>"","OK","CHECK: note required"),"CHECK")))) -> OK
A40: SERH0039 | B40: 8 | C40: W000014515 | D40: Louisa May Alcott | E40: Louisa May Alcott | F40: OL29984W | G40: OL32311079M | H40: Louisa May Alcott | I40: Her Life, Letters, and Journals | J40: Oct 28, 2018 | K40: Franklin Classics Trade Press | L40: /authors/OL26680A || /authors/OL2414275A | M40: 434 | N40: HIGH | O40: ASSIGN_COMPONENT | P40: W000014515_C01 | Q40: HIGH | R40: Title/subtitle 'Her Life, Letters, and Journals'. | S40: =IF(P40="","",IFERROR(VLOOKUP(P40,Components!$E$2:$H$83,3,FALSE()),"INVALID")) -> Her Life, Letters, and Journals | T40: =IF(P40="","",IFERROR(VLOOKUP(P40,Components!$E$2:$H$83,4,FALSE()),"INVALID")) -> PRIMARY_SUCCESSOR_HINT | U40: =IF(O40="","",IF(O40="ASSIGN_COMPONENT",IF(P40<>"","OK","CHECK: component required"),IF(O40="HOLD_UNRESOLVED",IF(P40="","OK","CHECK: clear component"),IF(O40="REGISTRY_ISSUE",IF(R40<>"","OK","CHECK: note required"),"CHECK")))) -> OK
...

Sheet Components
A1: remediation_priority_rank | B1: project_work_id | C1: r2_target_title | D1: r2_target_author | E1: component_id | F1: component_local_id | G1: component_label | H1: human_role_hint | I1: component_definition | J1: human_resolution_confidence
A2: 1 | B2: W000014024 | C2: Henry James | D2: Henry James | E2: W000014024_C01 | F2: C01 | G2: Autobiography | H2: SUCCESSOR | I2: Henry James editions identified as autobiography. | J2: HIGH
A3: 1 | B3: W000014024 | C3: Henry James | D3: Henry James | E3: W000014024_C02 | F3: C02 | G3: Letters to A.C. Benson and Auguste Monod | H3: SUCCESSOR | I3: The correspondence volume Letters to A.C. Benson and Auguste Monod. | J3: HIGH
A4: 1 | B4: W000014024 | C4: Henry James | D4: Henry James | E4: W000014024_C03 | F4: C03 | G4: A Life in Letters | H4: SUCCESSOR | I4: Editions of A Life in Letters. | J4: HIGH
A5: 1 | B5: W000014024 | C5: Henry James | D5: Henry James | E5: W000014024_C04 | F5: C04 | G5: Stories and tales selections | H5: SUCCESSOR | I5: Collected Stories, Selected Tales, stories of the supernatural, seven stories and studies, and substantially equivalent story/tale selections. | J5: HIGH
A6: 1 | B6: W000014024 | C6: Henry James | D6: Henry James | E6: W000014024_C05 | F6: C05 | G6: Selected-fiction / selected-novels omnibus | H6: SUCCESSOR | I6: Omnibus or selected-fiction editions combining named Henry James fiction, including Daisy Miller, Washington Square, The Portrait of a Lady, The Bostonians, and The Aspern Papers. Treat the omnibus as one edition-level component; do not split it into constituent novels. | J6: HIGH
A7: 1 | B7: W000014024 | C7: Henry James | D7: Henry James | E7: W000014024_C06 | F7: C06 | G7: Critical essays / essays on art and drama | H7: SUCCESSOR | I7: Critical-essay collections and essays on art or drama. | J7: HIGH
A8: 1 | B8: W000014024 | C8: Henry James | D8: Henry James | E8: W000014024_C07 | F8: C07 | G8: The Spoils of Poynton — Bodley Head volume | H8: SUCCESSOR | I8: The Bodley Head volume explicitly identified as The Spoils of Poynton. | J8: HIGH
A9: 1 | B9: W000014024 | C9: Henry James | D9: Henry James | E9: W000014024_C08 | F9: C08 | G9: Representative selections | H9: SUCCESSOR | I9: The 1941 representative-selections publication and clear manifestations of it. | J9: HIGH
A10: 2 | B10: W000031472 | C10: Galen | D10: Galen | E10: W000031472_C01 | F10: C01 | G10: On the Properties of Foodstuffs | H10: SUCCESSOR | I10: On the Properties of Foodstuffs / De alimentorum facultatibus. | J10: HIGH
A11: 2 | B11: W000031472 | C11: Galen | D11: Galen | E11: W000031472_C02 | F11: C02 | G11: On Diseases and Symptoms | H11: SUCCESSOR | I11: On Diseases and Symptoms. | J11: HIGH
A12: 2 | B12: W000031472 | C12: Galen | D12: Galen | E12: W000031472_C03 | F12: C03 | G12: On Antecedent Causes | H12: SUCCESSOR | I12: On Antecedent Causes. | J12: HIGH
... A83: 23 | B83: W000004923 | C83: Poems | D83: Rubén Darío | E83: W000004923_C06 | F83: C06 | G83: Cuentos / prose stories | H83: DETACH | I83: Cuentos and prose-story material that is not part of the poetry identity. | J83: HIGH

Sheet ValidationLists
A1: human_routing_decision | B1: human_confidence | D1: W000002404 | E1: W000003023 | F1: W000003030 | G1: W000004772 | H1: W000004821 | I1: W000004923 | J1: W000005351 | K1: W000005423 | L1: W000005682 | M1: W000013400 | N1: W000014024 | O1: W000014515 | P1: W000021761 | Q1: W000023649 | R1: W000030489 | S1: W000030498 | T1: W000031472
A2: ASSIGN_COMPONENT | B2: HIGH | D2: W000002404_C01 | E2: W000003023_C01 | F2: W000003030_C01 | G2: W000004772_C01 | H2: W000004821_C01 | I2: W000004923_C01 | J2: W000005351_C01 | K2: W000005423_C01 | L2: W000005682_C01 | M2: W000013400_C01 | N2: W000014024_C01 | O2: W000014515_C01 | P2: W000021761_C01 | Q2: W000023649_C01 | R2: W000030489_C01 | S2: W000030498_C01 | T2: W000031472_C01
A3: HOLD_UNRESOLVED | B3: MEDIUM | D3: W000002404_C02 | E3: W000003023_C02 | F3: W000003030_C02 | G3: W000004772_C02 | H3: W000004821_C02 | I3: W000004923_C02 | J3: W000005351_C02 | K3: W000005423_C02 | L3: W000005682_C02 | M3: W000013400_C02 | N3: W000014024_C02 | O3: W000014515_C02 | P3: W000021761_C02 | Q3: W000023649_C02 | R3: W000030489_C02 | S3: W000030498_C02 | T3: W000031472_C02
A4: REGISTRY_ISSUE | B4: LOW | D4: W000002404_C03 | E4: W000003023_C03 | G4: W000004772_C03 | H4: W000004821_C03 | I4: W000004923_C03 | J4: W000005351_C03 | K4: W000005423_C03 | L4: W000005682_C03 | M4: W000013400_C03 | N4: W000014024_C03 | O4: W000014515_C03 | P4: W000021761_C03 | Q4: W000023649_C03 | R4: W000030489_C03 | S4: W000030498_C03 | T4: W000031472_C03
D5: W000002404_C04 | G5: W000004772_C04 | H5: W000004821_C04 | I5: W000004923_C04 | J5: W000005351_C04 | K5: W000005423_C04 | L5: W000005682_C04 | M5: W000013400_C04 | N5: W000014024_C04 | O5: W000014515_C04 | P5: W000021761_C04 | Q5: W000023649_C04 | S5: W000030498_C04
H6: W000004821_C05 | I6: W000004923_C05 | K6: W000005423_C05 | N6: W000014024_C05 | O6: W000014515_C05 | P6: W000021761_C05 | Q6: W000023649_C05 | S6: W000030498_C05
H7: W000004821_C06 | I7: W000004923_C06 | K7: W000005423_C06 | N7: W000014024_C06 | O7: W000014515_C06 | P7: W000021761_C06 | S7: W000030498_C06
H8: W000004821_C07 | N8: W000014024_C07
H9: W000004821_C08 | N9: W000014024_C08
